Workbook

Sheet India CPI Inflation -CSV
A1: Sector | B1: Year | C1: Month | D1: Cereals and products | E1: Meat and fish | F1: Egg | G1: Milk and products | H1: Oils and fats | I1: Fruits | J1: Vegetables | K1: Pulses and products | L1: Sugar and Confectionery | M1: Spices | N1: Non-alcoholic beverages | O1: Prepared meals, snacks, sweets etc. | P1: Food and beverages | Q1: Pan, tobacco and intoxicants | R1: Clothing | S1: Footwear | T1: Clothing and footwear | U1: Housing | V1: Fuel and light | W1: Household goods and services | X1: Health | Y1: Transport and communication | Z1: Recreation and amusement | AA1: Education | AB1: Personal care and effects | AC1: Miscellaneous | AD1: General index
A2: Rural | B2: 2013 | C2: January | D2: 107.5 | E2: 106.3 | F2: 108.1 | G2: 104.9 | H2: 106.1 | I2: 103.9 | J2: 101.9 | K2: 106.1 | L2: 106.8 | M2: 103.1 | N2: 104.8 | O2: 106.7 | P2: 105.5 | Q2: 105.1 | R2: 106.5 | S2: 105.8 | T2: 106.4 | U2: NA | V2: 105.5 | W2: 104.8 | X2: 104 | Y2: 103.3 | Z2: 103.4 | AA2: 103.8 | AB2: 104.7 | AC2: 104 | AD2: 105.1
A3: Urban | B3: 2013 | C3: January | D3: 110.5 | E3: 109.1 | F3: 113 | G3: 103.6 | H3: 103.4 | I3: 102.3 | J3: 102.9 | K3: 105.8 | L3: 105.1 | M3: 101.8 | N3: 105.1 | O3: 107.9 | P3: 105.9 | Q3: 105.2 | R3: 105.9 | S3: 105 | T3: 105.8 | U3: 100.3 | V3: 105.4 | W3: 104.8 | X3: 104.1 | Y3: 103.2 | Z3: 102.9 | AA3: 103.5 | AB3: 104.3 | AC3: 103.7 | AD3: 104
A4: Rural+Urban | B4: 2013 | C4: January | D4: 108.4 | E4: 107.3 | F4: 110 | G4: 104.4 | H4: 105.1 | I4: 103.2 | J4: 102.2 | K4: 106 | L4: 106.2 | M4: 102.7 | N4: 104.9 | O4: 107.3 | P4: 105.6 | Q4: 105.1 | R4: 106.3 | S4: 105.5 | T4: 106.2 | U4: 100.3 | V4: 105.5 | W4: 104.8 | X4: 104 | Y4: 103.2 | Z4: 103.1 | AA4: 103.6 | AB4: 104.5 | AC4: 103.9 | AD4: 104.6
A5: Rural | B5: 2013 | C5: February | D5: 109.2 | E5: 108.7 | F5: 110.2 | G5: 105.4 | H5: 106.7 | I5: 104 | J5: 102.4 | K5: 105.9 | L5: 105.7 | M5: 103.1 | N5: 105.1 | O5: 107.7 | P5: 106.3 | Q5: 105.6 | R5: 107.1 | S5: 106.3 | T5: 107 | U5: NA | V5: 106.2 | W5: 105.2 | X5: 104.4 | Y5: 103.9 | Z5: 104 | AA5: 104.1 | AB5: 104.6 | AC5: 104.4 | AD5: 105.8
A6: Urban | B6: 2013 | C6: February | D6: 112.9 | E6: 112.9 | F6: 116.9 | G6: 104 | H6: 103.5 | I6: 103.1 | J6: 104.9 | K6: 104.1 | L6: 103.8 | M6: 102.3 | N6: 106 | O6: 109 | P6: 107.2 | Q6: 106 | R6: 106.6 | S6: 105.5 | T6: 106.4 | U6: 100.4 | V6: 105.7 | W6: 105.2 | X6: 104.7 | Y6: 104.4 | Z6: 103.3 | AA6: 103.7 | AB6: 104.3 | AC6: 104.3 | AD6: 104.7
A7: Rural+Urban | B7: 2013 | C7: February | D7: 110.4 | E7: 110.2 | F7: 112.8 | G7: 104.9 | H7: 105.5 | I7: 103.6 | J7: 103.2 | K7: 105.3 | L7: 105.1 | M7: 102.8 | N7: 105.5 | O7: 108.3 | P7: 106.6 | Q7: 105.7 | R7: 106.9 | S7: 106 | T7: 106.8 | U7: 100.4 | V7: 106 | W7: 105.2 | X7: 104.5 | Y7: 104.2 | Z7: 103.6 | AA7: 103.9 | AB7: 104.5 | AC7: 104.4 | AD7: 105.3
A8: Rural | B8: 2013 | C8: March | D8: 110.2 | E8: 108.8 | F8: 109.9 | G8: 105.6 | H8: 106.2 | I8: 105.7 | J8: 101.4 | K8: 105.7 | L8: 105 | M8: 103.3 | N8: 105.6 | O8: 108.2 | P8: 106.6 | Q8: 106.5 | R8: 107.6 | S8: 106.8 | T8: 107.5 | U8: NA | V8: 106.1 | W8: 105.6 | X8: 104.7 | Y8: 104.6 | Z8: 104 | AA8: 104.3 | AB8: 104.3 | AC8: 104.6 | AD8: 106
A9: Urban | B9: 2013 | C9: March | D9: 113.9 | E9: 111.4 | F9: 113.2 | G9: 104.3 | H9: 102.7 | I9: 104.9 | J9: 103.8 | K9: 103.5 | L9: 102.6 | M9: 102.4 | N9: 107 | O9: 109.8 | P9: 107.3 | Q9: 106.8 | R9: 107.2 | S9: 106 | T9: 107 | U9: 100.4 | V9: 106 | W9: 105.7 | X9: 105.2 | Y9: 105.5 | Z9: 103.5 | AA9: 103.8 | AB9: 104.2 | AC9: 104.9 | AD9: 105
A10: Rural+Urban | B10: 2013 | C10: March | D10: 111.4 | E10: 109.7 | F10: 111.2 | G10: 105.1 | H10: 104.9 | I10: 105.3 | J10: 102.2 | K10: 105 | L10: 104.2 | M10: 103 | N10: 106.2 | O10: 108.9 | P10: 106.9 | Q10: 106.6 | R10: 107.4 | S10: 106.5 | T10: 107.3 | U10: 100.4 | V10: 106.1 | W10: 105.6 | X10: 104.9 | Y10: 105.1 | Z10: 103.7 | AA10: 104 | AB10: 104.3 | AC10: 104.7 | AD10: 105.5
A11: Rural | B11: 2013 | C11: April | D11: 110.2 | E11: 109.5 | F11: 106.9 | G11: 106.3 | H11: 105.7 | I11: 108.3 | J11: 103.4 | K11: 105.7 | L11: 104.2 | M11: 103.2 | N11: 106.5 | O11: 108.8 | P11: 107.1 | Q11: 107.1 | R11: 108.1 | S11: 107.4 | T11: 108 | U11: NA | V11: 106.5 | W11: 106.1 | X11: 105.1 | Y11: 104.4 | Z11: 104.5 | AA11: 104.8 | AB11: 102.7 | AC11: 104.6 | AD11: 106.4
A12: Urban | B12: 2013 | C12: April | D12: 114.6 | E12: 113.4 | F12: 106 | G12: 104.7 | H12: 102.1 | I12: 109.5 | J12: 109.7 | K12: 104.6 | L12: 102 | M12: 103.5 | N12: 108.2 | O12: 110.6 | P12: 108.8 | Q12: 108.5 | R12: 107.9 | S12: 106.4 | T12: 107.7 | U12: 100.5 | V12: 106.4 | W12: 106.5 | X12: 105.7 | Y12: 105 | Z12: 104 | AA12: 105.2 | AB12: 103.2 | AC12: 105.1 | AD12: 105.7
A13: Rural+Urban | B13: 2013 | C13: April | D13: 111.6 | E13: 110.9 | F13: 106.6 | G13: 105.7 | H13: 104.4 | I13: 108.9 | J13: 105.5 | K13: 105.3 | L13: 103.5 | M13: 103.3 | N13: 107.2 | O13: 109.6 | P13: 107.7 | Q13: 107.5 | R13: 108 | S13: 107 | T13: 107.9 | U13: 100.5 | V13: 106.5 | W13: 106.3 | X13: 105.3 | Y13: 104.7 | Z13: 104.2 | AA13: 105 | AB13: 102.9 | AC13: 104.8 | AD13: 106.1
... A259: Rural+Urban | B259: 2020 | C259: March | D259: 145.1 | E259: 167 | F259: 148.1 | G259: 151.5 | H259: 131.2 | I259: 142.5 | J259: 157.3 | K259: 141.1 | L259: 113.2 | M259: 153.2 | N259: 136.7 | O259: 159.6 | P259: 148.9 | Q259: 171.2 | R259: 151.2 | S259: 141.9 | T259: 149.8 | U259: 154.5 | V259: 148.9 | W259: 146.4 | X259: 152.3 | Y259: 129.9 | Z259: 143.7 | AA259: 156.1 | AB259: 145.2 | AC259: 143.8 | AD259: 148.6
A260: Rural | B260: 2020 | C260: April | D260: 147.2 | F260: 146.9 | G260: 155.6 | H260: 137.1 | I260: 147.3 | J260: 162.7 | K260: 150.2 | L260: 119.8 | M260: 158.7 | N260: 139.2 | P260: 150.1 | U260: NA | V260: 148.4 | X260: 154.3
A261: Urban | B261: 2020 | C261: April | D261: 151.8 | F261: 151.9 | G261: 155.5 | H261: 131.6 | I261: 152.9 | J261: 180 | K261: 150.8 | L261: 121.2 | M261: 154 | N261: 133.5 | P261: 153.5 | U261: 155.6 | V261: 137.1 | X261: 144.8
A262: Rural+Urban | B262: 2020 | C262: April | D262: 148.7 | F262: 148.8 | G262: 155.6 | H262: 135.1 | I262: 149.9 | J262: 168.6 | K262: 150.4 | L262: 120.3 | M262: 157.1 | N262: 136.8 | P262: 151.4 | U262: 155.6 | V262: 144.1 | X262: 150.7 | AD262: 150.3
A263: Rural | B263: 2020 | C263: May | U263: NA
A264: Urban | B264: 2020 | C264: May | U264: NA
A265: Rural+Urban | B265: 2020 | C265: May | U265: NA | AD265: =AVERAGE(AD256:AD262,AD268:AD274) -> 151.14167
A266: Rural | B266: 2020 | C266: June | D266: 148.2 | E266: 190.3 | F266: 149.4 | G266: 153.3 | H266: 138.2 | I266: 143.2 | J266: 148.9 | K266: 150.3 | L266: 113.2 | M266: 159.8 | N266: 142.1 | O266: 161.8 | P266: 152.3 | Q266: 182.4 | R266: 154.7 | S266: 150 | T266: 154.1 | U266: NA | V266: 144.9 | W266: 151.7 | X266: 158.2 | Y266: 141.4 | Z266: 153.2 | AA266: 161.8 | AB266: 151.2 | AC266: 151.7 | AD266: 152.7
A267: Urban | B267: 2020 | C267: June | D267: 152.7 | E267: 197 | F267: 154.6 | G267: 153.4 | H267: 132.9 | I267: 151.8 | J267: 171.2 | K267: 152 | L267: 116.3 | M267: 158.8 | N267: 135.6 | O267: 161.7 | P267: 157 | Q267: 186.7 | R267: 149.1 | S267: 136.6 | T267: 147.2 | U267: 154.7 | V267: 137.1 | W267: 140.4 | X267: 148.1 | Y267: 129.3 | Z267: 144.5 | AA267: 152.5 | AB267: 152.2 | AC267: 142 | AD267: 150.8
A268: Rural+Urban | B268: 2020 | C268: June | D268: 149.6 | E268: 192.7 | F268: 151.4 | G268: 153.3 | H268: 136.3 | I268: 147.2 | J268: 156.5 | K268: 150.9 | L268: 114.2 | M268: 159.5 | N268: 139.4 | O268: 161.8 | P268: 154 | Q268: 183.5 | R268: 152.5 | S268: 144.4 | T268: 151.4 | U268: 154.7 | V268: 141.9 | W268: 146.4 | X268: 154.4 | Y268: 135 | Z268: 148.3 | AA268: 156.4 | AB268: 151.6 | AC268: 147 | AD268: 151.8
A269: Rural | B269: 2020 | C269: July | D269: 148.2 | E269: 190.3 | F269: 149.4 | G269: 153.3 | H269: 138.2 | I269: 143.2 | J269: 148.9 | K269: 150.3 | L269: 113.2 | M269: 159.8 | N269: 142.1 | O269: 161.8 | P269: 152.3 | Q269: 182.4 | R269: 154.7 | S269: 150 | T269: 154.1 | U269: NA | V269: 144.9 | W269: 151.7 | X269: 158.2 | Y269: 141.4 | Z269: 153.2 | AA269: 161.8 | AB269: 151.2 | AC269: 151.7 | AD269: 152.7
A270: Urban | B270: 2020 | C270: July | D270: 152.7 | E270: 197 | F270: 154.6 | G270: 153.4 | H270: 132.9 | I270: 151.8 | J270: 171.2 | K270: 152 | L270: 116.3 | M270: 158.8 | N270: 135.6 | O270: 161.7 | P270: 157 | Q270: 186.7 | R270: 149.1 | S270: 136.6 | T270: 147.2 | U270: 154.7 | V270: 137.1 | W270: 140.4 | X270: 148.1 | Y270: 129.3 | Z270: 144.5 | AA270: 152.5 | AB270: 152.2 | AC270: 142 | AD270: 150.8
A271: Rural+Urban | B271: 2020 | C271: July | D271: 149.6 | E271: 192.7 | F271: 151.4 | G271: 153.3 | H271: 136.3 | I271: 147.2 | J271: 156.5 | K271: 150.9 | L271: 114.2 | M271: 159.5 | N271: 139.4 | O271: 161.8 | P271: 154 | Q271: 183.5 | R271: 152.5 | S271: 144.4 | T271: 151.4 | U271: 154.7 | V271: 141.9 | W271: 146.4 | X271: 154.4 | Y271: 135 | Z271: 148.3 | AA271: 156.4 | AB271: 151.6 | AC271: 147 | AD271: 151.8
A272: Rural | B272: 2020 | C272: August | D272: 147.6 | E272: 187.2 | F272: 148.4 | G272: 153.3 | H272: 139.8 | I272: 146.9 | J272: 171 | K272: 149.9 | L272: 114.2 | M272: 160 | N272: 143.5 | O272: 161.5 | P272: 155.3 | Q272: 180.9 | R272: 155.1 | S272: 149.3 | T272: 154.3 | U272: NA | V272: 145.8 | W272: 151.9 | X272: 158.8 | Y272: 143.6 | Z272: 152.2 | AA272: 162.7 | AB272: 153.6 | AC272: 153 | AD272: 154.7
A273: Urban | B273: 2020 | C273: August | D273: 151.6 | E273: 197.8 | F273: 154.5 | G273: 153.4 | H273: 133.4 | I273: 154.5 | J273: 191.9 | K273: 151.3 | L273: 116.8 | M273: 160 | N273: 136.5 | O273: 163.3 | P273: 159.9 | Q273: 187.2 | R273: 150 | S273: 135.2 | T273: 147.8 | U273: 155.5 | V273: 138.3 | W273: 144.5 | X273: 148.7 | Y273: 133.9 | Z273: 141.2 | AA273: 155.5 | AB273: 155.2 | AC273: 144.8 | AD273: 152.9
A274: Rural+Urban | B274: 2020 | C274: August | D274: 148.9 | E274: 190.9 | F274: 150.8 | G274: 153.3 | H274: 137.4 | I274: 150.4 | J274: 178.1 | K274: 150.4 | L274: 115.1 | M274: 160 | N274: 140.6 | O274: 162.3 | P274: 157 | Q274: 182.6 | R274: 153.1 | S274: 143.4 | T274: 151.7 | U274: 155.5 | V274: 143 | W274: 148.4 | X274: 155 | Y274: 138.5 | Z274: 146 | AA274: 158.5 | AB274: 154.3 | AC274: 149 | AD274: 153.9
A275: Rural | B275: 2020 | C275: September | D275: 146.9 | E275: 183.9 | F275: 149.5 | G275: 153.4 | H275: 140.4 | I275: 147 | J275: 178.8 | K275: 149.3 | L275: 115.1 | M275: 160 | N275: 145.4 | O275: 161.6 | P275: 156.1 | Q275: 182.9 | R275: 155.4 | S275: 149.9 | T275: 154.6 | U275: NA | V275: 146.4 | W275: 151.6 | X275: 159.1 | Y275: 144.6 | Z275: 152.8 | AA275: 161.1 | AB275: 157.4 | AC275: 153.7 | AD275: 155.4
A276: Urban | B276: 2020 | C276: September | D276: 151.5 | E276: 193.1 | F276: 157.3 | G276: 153.9 | H276: 134.4 | I276: 155.4 | J276: 202 | K276: 150.8 | L276: 118.9 | M276: 160.9 | N276: 137.7 | O276: 164.4 | P276: 161.3 | Q276: 188.7 | R276: 150.2 | S276: 136.3 | T276: 148.1 | U276: 156.3 | V276: 137.2 | W276: 145.4 | X276: 150 | Y276: 135.1 | Z276: 141.8 | AA276: 154.9 | AB276: 159.8 | AC276: 146 | AD276: 154
A277: Rural+Urban | B277: 2020 | C277: September | D277: 148.4 | E277: 187.1 | F277: 152.5 | G277: 153.6 | H277: 138.2 | I277: 150.9 | J277: 186.7 | K277: 149.8 | L277: 116.4 | M277: 160.3 | N277: 142.2 | O277: 162.9 | P277: 158 | Q277: 184.4 | R277: 153.4 | S277: 144.3 | T277: 152 | U277: 156.3 | V277: 142.9 | W277: 148.7 | X277: 155.6 | Y277: 139.6 | Z277: 146.6 | AA277: 157.5 | AB277: 158.4 | AC277: 150 | AD277: 154.7
... A373: Rural+Urban | B373: 2023 | C373: May | D373: 173.7 | E373: 214.3 | F373: 173.2 | G373: 179.5 | H373: 170 | I373: 172.2 | J373: 161 | K373: 175.6 | L373: 122.7 | M373: 218 | N373: 173.4 | O373: 194.2 | P373: 179.1 | Q373: 201 | R373: 187.3 | S373: 179.7 | T373: 186.2 | U373: 175.6 | V373: 182.8 | W373: 175.2 | X373: 185.7 | Y373: 164.8 | Z373: 171.2 | AA373: 177.1 | AB373: 185.2 | AC373: 175.7 | AD373: 179.1

Sheet Category
B1: Sub-category | C1: Category
B3: Cereals and products | C3: Food & Beverages
B4: Meat and fish
B5: Egg
B6: Milk and products
B7: Oils and fats
B8: Fruits
B9: Vegetables
B10: Pulses and products
B11: Sugar and Confectionery
B12: Spices
B13: Non-alcoholic beverages
B14: Prepared meals, snacks, sweets etc.
B15: Food and beverages
B16: Pan, tobacco and intoxicants
B18: Clothing | C18: Clothing & Footwear
B19: Footwear
B20: Clothing and footwear
B22: Housing | C22: Housing
B23: Household goods and services
B25: Health | C25: Health
B26: Personal care and effects
B28: Transportation & Comm | C28: Transportation & Communication
B29: Fuel and light
B31: Education | C31: Education
B33: Recreation and amusement | C33: Recreation & Misc
B34: Miscellaneous

Sheet Data Dictionary
B1: Remarks
A2: Sector | B2: Which sectors the data belongs to- Urban, Rural, Rural+ Urban
A3: Year | B3: 2013-2023- Span of 10yrs(Jan to May)
B6: All sub categories which are defined in next category sheet

Sheet Collated sheet Category wise
A1: Sector | B1: Year | C1: Month | D1: Month-Year | E1: Datewise (Helper Coln) | F1: Food & beverages | G1: Clothing & Footwear | H1: Housing | I1: Health | J1: Transportation & Communcation | K1: Education | L1: Recreation & Misc | M1: General Index
A2: ='[1]14- All_India_Index_Upto_April2'!A2 -> Rural | B2: ='[1]14- All_India_Index_Upto_April2'!B2 -> 2013 | C2: ='[1]14- All_India_Index_Upto_April2'!C2 -> January | D2: =_xlfn.TEXTJOIN("-",0,C2,B2) -> January-2013 | E2: =DATEVALUE("1-" &D2) -> 41275 | F2: =SUM('[1]14- All_India_Index_Upto_April2'!F2:S2) -> 1476.8 | G2: =SUM('[1]14- All_India_Index_Upto_April2'!T2:V2) -> 318.7 | H2: =SUM([1]!_14__All_India_Index_Upto_April2[[#This Row],[Housing new]],[1]!_14__All_India_Index_Upto_April2[[#This Row],[Household goods and services]]) -> #REF! | I2: =SUM('[1]14- All_India_Index_Upto_April2'!Z2,'[1]14- All_India_Index_Upto_April2'!AD2) -> 208.7 | J2: =SUM('[1]14- All_India_Index_Upto_April2'!AA2) -> 103.3 | K2: ='[1]14- All_India_Index_Upto_April2'!AC2 -> 103.8 | L2: =SUM('[1]14- All_India_Index_Upto_April2'!AB2,'[1]14- All_India_Index_Upto_April2'!AE2) -> 207.4 | M2: ='[1]14- All_India_Index_Upto_April2'!AF2 -> 105.1
A3: ='[1]14- All_India_Index_Upto_April2'!A3 -> Urban | B3: ='[1]14- All_India_Index_Upto_April2'!B3 -> 2013 | C3: ='[1]14- All_India_Index_Upto_April2'!C3 -> January | D3: =_xlfn.TEXTJOIN("-",0,C3,B3) -> January-2013 | E3: =DATEVALUE("1-" &D3) -> 41275 | F3: =SUM('[1]14- All_India_Index_Upto_April2'!F3:S3) -> 1481.6 | G3: =SUM('[1]14- All_India_Index_Upto_April2'!T3:V3) -> 316.7 | H3: =SUM([1]!_14__All_India_Index_Upto_April2[[#This Row],[Housing new]],[1]!_14__All_India_Index_Upto_April2[[#This Row],[Household goods and services]]) -> #REF! | I3: =SUM('[1]14- All_India_Index_Upto_April2'!Z3,'[1]14- All_India_Index_Upto_April2'!AD3) -> 208.4 | J3: =SUM('[1]14- All_India_Index_Upto_April2'!AA3) -> 103.2 | K3: ='[1]14- All_India_Index_Upto_April2'!AC3 -> 103.5 | L3: =SUM('[1]14- All_India_Index_Upto_April2'!AB3,'[1]14- All_India_Index_Upto_April2'!AE3) -> 206.6 | M3: ='[1]14- All_India_Index_Upto_April2'!AF3 -> 104
A4: ='[1]14- All_India_Index_Upto_April2'!A4 -> Rural+Urban | B4: ='[1]14- All_India_Index_Upto_April2'!B4 -> 2013 | C4: ='[1]14- All_India_Index_Upto_April2'!C4 -> January | D4: =_xlfn.TEXTJOIN("-",0,C4,B4) -> January-2013 | E4: =DATEVALUE("1-" &D4) -> 41275 | F4: =SUM('[1]14- All_India_Index_Upto_April2'!F4:S4) -> 1478.4 | G4: =SUM('[1]14- All_India_Index_Upto_April2'!T4:V4) -> 318 | H4: =SUM([1]!_14__All_India_Index_Upto_April2[[#This Row],[Housing new]],[1]!_14__All_India_Index_Upto_April2[[#This Row],[Household goods and services]]) -> #REF! | I4: =SUM('[1]14- All_India_Index_Upto_April2'!Z4,'[1]14- All_India_Index_Upto_April2'!AD4) -> 208.5 | J4: =SUM('[1]14- All_India_Index_Upto_April2'!AA4) -> 103.2 | K4: ='[1]14- All_India_Index_Upto_April2'!AC4 -> 103.6 | L4: =SUM('[1]14- All_India_Index_Upto_April2'!AB4,'[1]14- All_India_Index_Upto_April2'!AE4) -> 207 | M4: ='[1]14- All_India_Index_Upto_April2'!AF4 -> 104.6
A5: ='[1]14- All_India_Index_Upto_April2'!A5 -> Rural | B5: ='[1]14- All_India_Index_Upto_April2'!B5 -> 2013 | C5: ='[1]14- All_India_Index_Upto_April2'!C5 -> February | D5: =_xlfn.TEXTJOIN("-",0,C5,B5) -> February-2013 | E5: =DATEVALUE("1-" &D5) -> 41306 | F5: =SUM('[1]14- All_India_Index_Upto_April2'!F5:S5) -> 1486 | G5: =SUM('[1]14- All_India_Index_Upto_April2'!T5:V5) -> 320.4 | H5: =SUM([1]!_14__All_India_Index_Upto_April2[[#This Row],[Housing new]],[1]!_14__All_India_Index_Upto_April2[[#This Row],[Household goods and services]]) -> #REF! | I5: =SUM('[1]14- All_India_Index_Upto_April2'!Z5,'[1]14- All_India_Index_Upto_April2'!AD5) -> 209 | J5: =SUM('[1]14- All_India_Index_Upto_April2'!AA5) -> 103.9 | K5: ='[1]14- All_India_Index_Upto_April2'!AC5 -> 104.1 | L5: =SUM('[1]14- All_India_Index_Upto_April2'!AB5,'[1]14- All_India_Index_Upto_April2'!AE5) -> 208.4 | M5: ='[1]14- All_India_Index_Upto_April2'!AF5 -> 105.8
A6: ='[1]14- All_India_Index_Upto_April2'!A6 -> Urban | B6: ='[1]14- All_India_Index_Upto_April2'!B6 -> 2013 | C6: ='[1]14- All_India_Index_Upto_April2'!C6 -> February | D6: =_xlfn.TEXTJOIN("-",0,C6,B6) -> February-2013 | E6: =DATEVALUE("1-" &D6) -> 41306 | F6: =SUM('[1]14- All_India_Index_Upto_April2'!F6:S6) -> 1496.6 | G6: =SUM('[1]14- All_India_Index_Upto_April2'!T6:V6) -> 318.5 | H6: =SUM([1]!_14__All_India_Index_Upto_April2[[#This Row],[Housing new]],[1]!_14__All_India_Index_Upto_April2[[#This Row],[Household goods and services]]) -> #REF! | I6: =SUM('[1]14- All_India_Index_Upto_April2'!Z6,'[1]14- All_India_Index_Upto_April2'!AD6) -> 209 | J6: =SUM('[1]14- All_India_Index_Upto_April2'!AA6) -> 104.4 | K6: ='[1]14- All_India_Index_Upto_April2'!AC6 -> 103.7 | L6: =SUM('[1]14- All_India_Index_Upto_April2'!AB6,'[1]14- All_India_Index_Upto_April2'!AE6) -> 207.6 | M6: ='[1]14- All_India_Index_Upto_April2'!AF6 -> 104.7
A7: ='[1]14- All_India_Index_Upto_April2'!A7 -> Rural+Urban | B7: ='[1]14- All_India_Index_Upto_April2'!B7 -> 2013 | C7: ='[1]14- All_India_Index_Upto_April2'!C7 -> February | D7: =_xlfn.TEXTJOIN("-",0,C7,B7) -> February-2013 | E7: =DATEVALUE("1-" &D7) -> 41306 | F7: =SUM('[1]14- All_India_Index_Upto_April2'!F7:S7) -> 1489.9 | G7: =SUM('[1]14- All_India_Index_Upto_April2'!T7:V7) -> 319.7 | H7: =SUM([1]!_14__All_India_Index_Upto_April2[[#This Row],[Housing new]],[1]!_14__All_India_Index_Upto_April2[[#This Row],[Household goods and services]]) -> #REF! | I7: =SUM('[1]14- All_India_Index_Upto_April2'!Z7,'[1]14- All_India_Index_Upto_April2'!AD7) -> 209 | J7: =SUM('[1]14- All_India_Index_Upto_April2'!AA7) -> 104.2 | K7: ='[1]14- All_India_Index_Upto_April2'!AC7 -> 103.9 | L7: =SUM('[1]14- All_India_Index_Upto_April2'!AB7,'[1]14- All_India_Index_Upto_April2'!AE7) -> 208 | M7: ='[1]14- All_India_Index_Upto_April2'!AF7 -> 105.3
A8: ='[1]14- All_India_Index_Upto_April2'!A8 -> Rural | B8: ='[1]14- All_India_Index_Upto_April2'!B8 -> 2013 | C8: ='[1]14- All_India_Index_Upto_April2'!C8 -> March | D8: =_xlfn.TEXTJOIN("-",0,C8,B8) -> March-2013 | E8: =DATEVALUE("1-" &D8) -> 41334 | F8: =SUM('[1]14- All_India_Index_Upto_April2'!F8:S8) -> 1488.7 | G8: =SUM('[1]14- All_India_Index_Upto_April2'!T8:V8) -> 321.9 | H8: =SUM([1]!_14__All_India_Index_Upto_April2[[#This Row],[Housing new]],[1]!_14__All_India_Index_Upto_April2[[#This Row],[Household goods and services]]) -> #REF! | I8: =SUM('[1]14- All_India_Index_Upto_April2'!Z8,'[1]14- All_India_Index_Upto_April2'!AD8) -> 209 | J8: =SUM('[1]14- All_India_Index_Upto_April2'!AA8) -> 104.6 | K8: ='[1]14- All_India_Index_Upto_April2'!AC8 -> 104.3 | L8: =SUM('[1]14- All_India_Index_Upto_April2'!AB8,'[1]14- All_India_Index_Upto_April2'!AE8) -> 208.6 | M8: ='[1]14- All_India_Index_Upto_April2'!AF8 -> 106
A9: ='[1]14- All_India_Index_Upto_April2'!A9 -> Urban | B9: ='[1]14- All_India_Index_Upto_April2'!B9 -> 2013 | C9: ='[1]14- All_India_Index_Upto_April2'!C9 -> March | D9: =_xlfn.TEXTJOIN("-",0,C9,B9) -> March-2013 | E9: =DATEVALUE("1-" &D9) -> 41334 | F9: =SUM('[1]14- All_India_Index_Upto_April2'!F9:S9) -> 1493.6 | G9: =SUM('[1]14- All_India_Index_Upto_April2'!T9:V9) -> 320.2 | H9: =SUM([1]!_14__All_India_Index_Upto_April2[[#This Row],[Housing new]],[1]!_14__All_India_Index_Upto_April2[[#This Row],[Household goods and services]]) -> #REF! | I9: =SUM('[1]14- All_India_Index_Upto_April2'!Z9,'[1]14- All_India_Index_Upto_April2'!AD9) -> 209.4 | J9: =SUM('[1]14- All_India_Index_Upto_April2'!AA9) -> 105.5 | K9: ='[1]14- All_India_Index_Upto_April2'!AC9 -> 103.8 | L9: =SUM('[1]14- All_India_Index_Upto_April2'!AB9,'[1]14- All_India_Index_Upto_April2'!AE9) -> 208.4 | M9: ='[1]14- All_India_Index_Upto_April2'!AF9 -> 105
A10: ='[1]14- All_India_Index_Upto_April2'!A10 -> Rural+Urban | B10: ='[1]14- All_India_Index_Upto_April2'!B10 -> 2013 | C10: ='[1]14- All_India_Index_Upto_April2'!C10 -> March | D10: =_xlfn.TEXTJOIN("-",0,C10,B10) -> March-2013 | E10: =DATEVALUE("1-" &D10) -> 41334 | F10: =SUM('[1]14- All_India_Index_Upto_April2'!F10:S10) -> 1490.6 | G10: =SUM('[1]14- All_India_Index_Upto_April2'!T10:V10) -> 321.2 | H10: =SUM([1]!_14__All_India_Index_Upto_April2[[#This Row],[Housing new]],[1]!_14__All_India_Index_Upto_April2[[#This Row],[Household goods and services]]) -> #REF! | I10: =SUM('[1]14- All_India_Index_Upto_April2'!Z10,'[1]14- All_India_Index_Upto_April2'!AD10) -> 209.2 | J10: =SUM('[1]14- All_India_Index_Upto_April2'!AA10) -> 105.1 | K10: ='[1]14- All_India_Index_Upto_April2'!AC10 -> 104 | L10: =SUM('[1]14- All_India_Index_Upto_April2'!AB10,'[1]14- All_India_Index_Upto_April2'!AE10) -> 208.4 | M10: ='[1]14- All_India_Index_Upto_April2'!AF10 -> 105.5
A11: ='[1]14- All_India_Index_Upto_April2'!A11 -> Rural | B11: ='[1]14- All_India_Index_Upto_April2'!B11 -> 2013 | C11: ='[1]14- All_India_Index_Upto_April2'!C11 -> April | D11: =_xlfn.TEXTJOIN("-",0,C11,B11) -> April-2013 | E11: =DATEVALUE("1-" &D11) -> 41365 | F11: =SUM('[1]14- All_India_Index_Upto_April2'!F11:S11) -> 1492.9 | G11: =SUM('[1]14- All_India_Index_Upto_April2'!T11:V11) -> 323.5 | H11: =SUM([1]!_14__All_India_Index_Upto_April2[[#This Row],[Housing new]],[1]!_14__All_India_Index_Upto_April2[[#This Row],[Household goods and services]]) -> #REF! | I11: =SUM('[1]14- All_India_Index_Upto_April2'!Z11,'[1]14- All_India_Index_Upto_April2'!AD11) -> 207.8 | J11: =SUM('[1]14- All_India_Index_Upto_April2'!AA11) -> 104.4 | K11: ='[1]14- All_India_Index_Upto_April2'!AC11 -> 104.8 | L11: =SUM('[1]14- All_India_Index_Upto_April2'!AB11,'[1]14- All_India_Index_Upto_April2'!AE11) -> 209.1 | M11: ='[1]14- All_India_Index_Upto_April2'!AF11 -> 106.4
A12: ='[1]14- All_India_Index_Upto_April2'!A12 -> Urban | B12: ='[1]14- All_India_Index_Upto_April2'!B12 -> 2013 | C12: ='[1]14- All_India_Index_Upto_April2'!C12 -> April | D12: =_xlfn.TEXTJOIN("-",0,C12,B12) -> April-2013 | E12: =DATEVALUE("1-" &D12) -> 41365 | F12: =SUM('[1]14- All_India_Index_Upto_April2'!F12:S12) -> 1506.2 | G12: =SUM('[1]14- All_India_Index_Upto_April2'!T12:V12) -> 322 | H12: =SUM([1]!_14__All_India_Index_Upto_April2[[#This Row],[Housing new]],[1]!_14__All_India_Index_Upto_April2[[#This Row],[Household goods and services]]) -> #REF! | I12: =SUM('[1]14- All_India_Index_Upto_April2'!Z12,'[1]14- All_India_Index_Upto_April2'!AD12) -> 208.9 | J12: =SUM('[1]14- All_India_Index_Upto_April2'!AA12) -> 105 | K12: ='[1]14- All_India_Index_Upto_April2'!AC12 -> 105.2 | L12: =SUM('[1]14- All_India_Index_Upto_April2'!AB12,'[1]14- All_India_Index_Upto_April2'!AE12) -> 209.1 | M12: ='[1]14- All_India_Index_Upto_April2'!AF12 -> 105.7
A13: ='[1]14- All_India_Index_Upto_April2'!A13 -> Rural+Urban | B13: ='[1]14- All_India_Index_Upto_April2'!B13 -> 2013 | C13: ='[1]14- All_India_Index_Upto_April2'!C13 -> April | D13: =_xlfn.TEXTJOIN("-",0,C13,B13) -> April-2013 | E13: =DATEVALUE("1-" &D13) -> 41365 | F13: =SUM('[1]14- All_India_Index_Upto_April2'!F13:S13) -> 1497.7 | G13: =SUM('[1]14- All_India_Index_Upto_April2'!T13:V13) -> 322.9 | H13: =SUM([1]!_14__All_India_Index_Upto_April2[[#This Row],[Housing new]],[1]!_14__All_India_Index_Upto_April2[[#This Row],[Household goods and services]]) -> #REF! | I13: =SUM('[1]14- All_India_Index_Upto_April2'!Z13,'[1]14- All_India_Index_Upto_April2'!AD13) -> 208.2 | J13: =SUM('[1]14- All_India_Index_Upto_April2'!AA13) -> 104.7 | K13: ='[1]14- All_India_Index_Upto_April2'!AC13 -> 105 | L13: =SUM('[1]14- All_India_Index_Upto_April2'!AB13,'[1]14- All_India_Index_Upto_April2'!AE13) -> 209 | M13: ='[1]14- All_India_Index_Upto_April2'!AF13 -> 106.1
... A367: ='[1]14- All_India_Index_Upto_April2'!A367 -> Rural+Urban | B367: ='[1]14- All_India_Index_Upto_April2'!B367 -> 2023 | C367: ='[1]14- All_India_Index_Upto_April2'!C367 -> May | D367: =_xlfn.TEXTJOIN("-",0,C367,B367) -> May-2023 | E367: =DATEVALUE("1-" &D367) -> 45047 | F367: =SUM('[1]14- All_India_Index_Upto_April2'!F367:S367) -> 2507.9 | G367: =SUM('[1]14- All_India_Index_Upto_April2'!T367:V367) -> 553.2 | H367: =SUM([1]!_14__All_India_Index_Upto_April2[[#This Row],[Housing new]],[1]!_14__All_India_Index_Upto_April2[[#This Row],[Household goods and services]]) -> #REF! | I367: =SUM('[1]14- All_India_Index_Upto_April2'!Z367,'[1]14- All_India_Index_Upto_April2'!AD367) -> 370.9 | J367: =SUM('[1]14- All_India_Index_Upto_April2'!AA367) -> 164.8 | K367: ='[1]14- All_India_Index_Upto_April2'!AC367 -> 177.1 | L367: =SUM('[1]14- All_India_Index_Upto_April2'!AB367,'[1]14- All_India_Index_Upto_April2'!AE367) -> 346.9 | M367: ='[1]14- All_India_Index_Upto_April2'!AF367 -> 179.1

Sheet DA-1
B1: Contribution of Broader Categories towards CPI Basket
B3: \\To get the highest contributor for last month we need to add all index values as specified in the category sheet for latest month
B7: Categories | C7: Rural | D7: Contribution | E7: Urban | F7: Contribution | G7: Rural+Urban | H7: Contribution
B8: Food & beverages | C8: =SUM('India CPI Inflation -CSV'!D371:Q371) -> 2490.6 | D8: =$C8/$C$15*100 -> 55.36143 | E8: =SUM('India CPI Inflation -CSV'!D372:Q372) -> 2539.3 | F8: =$E8/$E$15*100 -> 57.347727 | G8: =SUM('India CPI Inflation -CSV'!D373:Q373) -> 2507.9 | H8: =$G8/$G$15*100 -> 56.510962
B9: Clothing & Footwear | C9: =SUM('India CPI Inflation -CSV'!R371:T371) -> 569.9 | D9: =$C9/$C$15*100 -> 12.667823 | E9: =SUM('India CPI Inflation -CSV'!R372:T372) -> 528.7 | F9: =$E9/$E$15*100 -> 11.940197 | G9: =SUM('India CPI Inflation -CSV'!R373:T373) -> 553.2 | H9: =$G9/$G$15*100 -> 12.465355
B10: Housing | C10: =SUM('India CPI Inflation -CSV'!U371,'India CPI Inflation -CSV'!W371) -> 179.8 | D10: =$C10/$C$15*100 -> 3.9966213 | E10: =SUM('India CPI Inflation -CSV'!U372,'India CPI Inflation -CSV'!W372) -> 170.1 | F10: =$E10/$E$15*100 -> 3.8415502 | G10: =SUM('India CPI Inflation -CSV'!U373,'India CPI Inflation -CSV'!W373) -> 175.2 | H10: =$G10/$G$15*100 -> 3.9478132
B11: Health | C11: =SUM('India CPI Inflation -CSV'!X371,'India CPI Inflation -CSV'!AB371) -> 372.7 | D11: =$C11/$C$15*100 -> 8.2844314 | E11: =SUM('India CPI Inflation -CSV'!X261,'India CPI Inflation -CSV'!AB372) -> 330.4 | F11: =$E11/$E$15*100 -> 7.4617765 | G11: =SUM('India CPI Inflation -CSV'!X261,'India CPI Inflation -CSV'!AB373) -> 330 | H11: =$G11/$G$15*100 -> 7.4359494
B12: Transportation & Communcation | C12: =SUM('India CPI Inflation -CSV'!V371,'India CPI Inflation -CSV'!Y371) -> 352.2 | D12: =$C12/$C$15*100 -> 7.8287543 | E12: =SUM('India CPI Inflation -CSV'!V372,'India CPI Inflation -CSV'!Y372) -> 343.8 | F12: =$E12/$E$15*100 -> 7.764403 | G12: =SUM('India CPI Inflation -CSV'!V373,'India CPI Inflation -CSV'!Y373) -> 347.6 | H12: =$G12/$G$15*100 -> 7.8325334
B13: Education | C13: =SUM('India CPI Inflation -CSV'!AA371) -> 180.3 | D13: =$C13/$C$15*100 -> 4.0077354 | E13: =SUM('India CPI Inflation -CSV'!AA372) -> 174.8 | F13: =$E13/$E$15*100 -> 3.9476953 | G13: =SUM('India CPI Inflation -CSV'!AA373) -> 177.1 | H13: =$G13/$G$15*100 -> 3.9906262
B14: Recreation & Misc | C14: =SUM('India CPI Inflation -CSV'!Z371,'India CPI Inflation -CSV'!AC371) -> 353.3 | D14: =$C14/$C$15*100 -> 7.8532053 | E14: =SUM('India CPI Inflation -CSV'!Z372,'India CPI Inflation -CSV'!AC372) -> 340.8 | F14: =$E14/$E$15*100 -> 7.6966508 | G14: =SUM('India CPI Inflation -CSV'!Z373,'India CPI Inflation -CSV'!AC373) -> 346.9 | H14: =$G14/$G$15*100 -> 7.8167602
B15: Total | C15: =SUM(C8:C14) -> 4498.8 | D15: =SUM(D8:D14) -> 100 | E15: =SUM(E8:E14) -> 4427.9 | F15: =$E15/$E$15*100 -> 100 | G15: =SUM(G8:G14) -> 4437.9 | H15: =$G15/$G$15*100 -> 100
B35: Food & beverage is the highest contribution towards CPI calculation in all 3 sectors
B36: Clothing & Footwear and housing are the mid contributors to CPI calculation
B37: whereas other category do contribute but not that much.

Sheet DA-2
B1: Trend of Y-o-Y increase in CPI (Rural + Urban) inflation starting from 2017 for the entire basket of products combined
B4: \\We have data from 2013 Jan to 2023 May
B5: \\So we will take 2017 May to 2023 May
B6: \\We will consider 2017 May also to get June data
B9: Sector | C9: Year | D9: Month | E9: General index | F9: Y-o-Y Calculation | G9: Y-o-Y%
B10: Rural+Urban | C10: 2016 | D10: May | E10: 128.6
B11: Rural+Urban | C11: 2017 | D11: May | E11: 131.4 | F11: =($E11-$E10)/$E10 -> 0.021772939 | G11: =($E11-$E10)/$E10 -> 0.021772939
B12: Rural+Urban | C12: 2018 | D12: May | E12: 137.8 | F12: =($E12-$E11)/$E11 -> 0.04870624 | G12: =($E12-$E11)/$E11 -> 0.04870624
B13: Rural+Urban | C13: 2019 | D13: May | E13: 142 | F13: =($E13-$E12)/$E12 -> 0.030478955 | G13: =($E13-$E12)/$E12 -> 0.030478955
B14: Rural+Urban | C14: 2020 | D14: May | E14: 151.14167 | F14: =($E14-$E13)/$E13 -> 0.064377934 | G14: =($E14-$E13)/$E13 -> 0.064377934
B15: Rural+Urban | C15: 2021 | D15: May | E15: 160.4 | F15: =($E15-$E14)/$E14 -> 0.061255996 | G15: =($E15-$E14)/$E14 -> 0.061255996
B16: Rural+Urban | C16: 2022 | D16: May | E16: 171.7 | F16: =($E16-$E15)/$E15 -> 0.070448878 | G16: =($E16-$E15)/$E15 -> 0.070448878
B17: Rural+Urban | C17: 2023 | D17: May | E17: 179.1 | F17: =($E17-$E16)/$E16 -> 0.043098427 | G17: =($E17-$E16)/$E16 -> 0.043098427
B20: For year 2022, inflation rate is highest at 7%
B22: As per research, due to Russia-Ukraine wars which disrupted the supply chains
B23: and because of that inflation rate is highest in 2022.

Sheet DA-3
B1: Trends in prices of food bucket category(M-o-M)
B3: \\India's retail inflation reaching a 3-month high of 5.55% in November 2023, largely due to a sharp rise in food prices
B4: \\We have to take 12 months ending May'2023
B5: \\ Data from June'2022 to May'2023
B7: Rural | H7: Urban | N7: Rural+Urban
B8: Year | C8: Month | D8: Food | E8: M-o-M | F8: M-o-M% | H8: Year | I8: Month | J8: Food | K8: M-o-M | L8: M-o-M% | N8: Year | O8: Month | P8: Food | Q8: M-o-M | R8: M-o-M%
B9: 2022 | C9: May | D9: 2419.7 | E9: =(D9-D8)/D8 -> #VALUE! | H9: 2022 | I9: May | J9: 2459.7 | K9: =(J9-J8)/J8 -> #VALUE! | N9: 2022 | O9: May | P9: 2433 | Q9: =(P9-P8)/P8 -> #VALUE!
B10: 2022 | C10: June | D10: 2441.2 | E10: =(D10-D9)/D9 -> 0.008885399 | F10: 0.008885399 | H10: 2022 | I10: June | J10: 2485.8 | K10: =(J10-J9)/J9 -> 0.01061105 | L10: 0.01061105 | N10: 2022 | O10: June | P10: 2456.2 | Q10: =(P10-P9)/P9 -> 0.0095355528 | R10: 0.0095355528
B11: 2022 | C11: July | D11: 2445.7 | E11: =(D11-D10)/D10 -> 0.0018433557 | F11: 0.0018433557 | H11: 2022 | I11: July | J11: 2490.2 | K11: =(J11-J10)/J10 -> 0.0017700539 | L11: 0.0017700539 | N11: 2022 | O11: July | P11: 2460.9 | Q11: =(P11-P10)/P10 -> 0.001913525 | R11: 0.001913525
B12: 2022 | C12: August | D12: 2449.5 | E12: =(D12-D11)/D11 -> 0.0015537474 | F12: 0.0015537474 | H12: 2022 | I12: August | J12: 2492.4 | K12: =(J12-J11)/J11 -> 0.00088346318 | L12: 0.00088346318 | N12: 2022 | O12: August | P12: 2464.2 | Q12: =(P12-P11)/P11 -> 0.0013409728 | R12: 0.0013409728
B13: 2022 | C13: September | D13: 2462.3 | E13: =(D13-D12)/D12 -> 0.0052255562 | F13: 0.0052255562 | H13: 2022 | I13: September | J13: 2506.1 | K13: =(J13-J12)/J12 -> 0.00549671 | L13: 0.00549671 | N13: 2022 | O13: September | P13: 2476.8 | Q13: =(P13-P12)/P12 -> 0.0051132213 | R13: 0.0051132213
B14: 2022 | C14: October | D14: 2479.4 | E14: =(D14-D13)/D13 -> 0.0069447265 | F14: 0.0069447265 | H14: 2022 | I14: October | J14: 2522.4 | K14: =(J14-J13)/J13 -> 0.0065041299 | L14: 0.0065041299 | N14: 2022 | O14: October | P14: 2493.6 | Q14: =(P14-P13)/P13 -> 0.0067829457 | R14: 0.0067829457
B15: 2022 | C15: November | D15: 2483.2 | E15: =(D15-D14)/D14 -> 0.0015326289 | F15: 0.0015326289 | H15: 2022 | I15: November | J15: 2515 | K15: =(J15-J14)/J14 -> -0.0029337139 | L15: -0.0029337139 | N15: 2022 | O15: November | P15: 2493.7 | Q15: =(P15-P14)/P14 -> 4.0102663e-05 | R15: 4.0102663e-05
B16: 2022 | C16: December | D16: 2473 | E16: =(D16-D15)/D15 -> -0.0041076031 | F16: -0.0041076031 | H16: 2022 | I16: December | J16: 2496.9 | K16: =(J16-J15)/J15 -> -0.0071968191 | L16: -0.0071968191 | N16: 2022 | O16: December | P16: 2480.7 | Q16: =(P16-P15)/P15 -> -0.0052131371 | R16: -0.0052131371
B17: 2023 | C17: January | D17: 2480.1 | E17: =(D17-D16)/D16 -> 0.0028710069 | F17: 0.0028710069 | H17: 2023 | I17: January | J17: 2511.8 | K17: =(J17-J16)/J16 -> 0.0059673996 | L17: 0.0059673996 | N17: 2023 | O17: January | P17: 2490.9 | Q17: =(P17-P16)/P16 -> 0.0041117427 | R17: 0.0041117427
B18: 2023 | C18: February | D18: 2464 | E18: =(D18-D17)/D17 -> -0.0064916737 | F18: -0.0064916737 | H18: 2023 | I18: February | J18: 2505.9 | K18: =(J18-J17)/J17 -> -0.0023489131 | L18: -0.0023489131 | N18: 2023 | O18: February | P18: 2478.6 | Q18: =(P18-P17)/P17 -> -0.0049379742 | R18: -0.0049379742
B19: 2023 | C19: March | D19: 2464.2 | E19: =(D19-D18)/D18 -> 8.1168831e-05 | F19: 8.1168831e-05 | H19: 2023 | I19: March | J19: 2506.1 | K19: =(J19-J18)/J18 -> 7.9811645e-05 | L19: 7.9811645e-05 | N19: 2023 | O19: March | P19: 2478.7 | Q19: =(P19-P18)/P18 -> 4.0345356e-05 | R19: 4.0345356e-05
B20: 2023 | C20: April | D20: 2473.7 | E20: =(D20-D19)/D19 -> 0.0038552066 | F20: 0.0038552066 | H20: 2023 | I20: April | J20: 2521.2 | K20: =(J20-J19)/J19 -> 0.0060252983 | L20: 0.0060252983 | N20: 2023 | O20: April | P20: 2490.2 | Q20: =(P20-P19)/P19 -> 0.0046395288 | R20: 0.0046395288
B21: 2023 | C21: May | D21: 2490.6 | E21: =(D21-D20)/D20 -> 0.0068318713 | F21: 0.0068318713 | H21: 2023 | I21: May | J21: 2539.3 | K21: =(J21-J20)/J20 -> 0.0071791211 | L21: 0.0071791211 | N21: 2023 | O21: May | P21: 2507.9 | Q21: =(P21-P20)/P20 -> 0.0071078628 | R21: 0.0071078628
B23: Month with Highest Inflation | E23: June'2022 with 0.9% | H23: Month with Highest Inflation | K23: June'2022 with 1.1% | N23: Month with Highest Inflation | P23: June'2022 with 1.0%
B24: Month with Lowest Inflation | E24: February'2023 with -0.6% | H24: Month with Lowest Inflation | K24: December'2022 with -0.7% | N24: Month with Lowest Inflation | P24: December'2022 with -0.5%

Sheet DA-4
A1: COVID-19 effects on India CPI
A3: \\As we have enough data, we will taking 3yrs back 2019 and 3yrs after 2019
A4: \\Consider Mar'20 as the onset of covid, and can compare the inflation trend before and after Mar'20 to see if there is a change in inflation % before and after
A5: \\We will be considering Healthcare,Food and Essential Service
A8: Rural
A9: Year | B9: Month | C9: Healthcare | D9: Food | E9: Essential Service(Tran&Comm) | F9: Metric | G9: Value
A10: 2017 | B10: March | C10: =AVERAGE('India CPI Inflation -CSV'!X152,'India CPI Inflation -CSV'!AB152) -> 126.95 | D10: =AVERAGE('India CPI Inflation -CSV'!D152:Q152) -> 133.76429 | E10: =AVERAGE('India CPI Inflation -CSV'!V152,'India CPI Inflation -CSV'!Y152) -> 127 | F10: Healthcare Avg (Pre-COVID 2017-2019) | G10: =AVERAGE(C10:C12) -> 124.85
A11: 2018 | B11: March | C11: =AVERAGE('India CPI Inflation -CSV'!X153,'India CPI Inflation -CSV'!AB153) -> 122.4 | D11: =AVERAGE('India CPI Inflation -CSV'!D153:Q153) -> 132.37143 | E11: =AVERAGE('India CPI Inflation -CSV'!V153,'India CPI Inflation -CSV'!Y153) -> 118.2 | F11: Healthcare Avg (Post-COVID 2020-2023) | G11: =AVERAGE(C13:C16) -> 125.825
A12: 2019 | B12: March | C12: =AVERAGE('India CPI Inflation -CSV'!X154,'India CPI Inflation -CSV'!AB154) -> 125.2 | D12: =AVERAGE('India CPI Inflation -CSV'!D154:Q154) -> 133.14286 | E12: =AVERAGE('India CPI Inflation -CSV'!V154,'India CPI Inflation -CSV'!Y154) -> 123.35 | F12: Food Avg (Pre-COVID 2017-2019) | G12: =AVERAGE(D10:D12) -> 133.09286
A13: 2020 | B13: March | C13: =AVERAGE('India CPI Inflation -CSV'!X155,'India CPI Inflation -CSV'!AB155) -> 127.35 | D13: =AVERAGE('India CPI Inflation -CSV'!D155:Q155) -> 133.62143 | E13: =AVERAGE('India CPI Inflation -CSV'!V155,'India CPI Inflation -CSV'!Y155) -> 127.1 | F13: Food Avg (Post-COVID 2020-2023) | G13: =AVERAGE(D13:D16) -> 133.27857
A14: 2021 | B14: March | C14: =AVERAGE('India CPI Inflation -CSV'!X156,'India CPI Inflation -CSV'!AB156) -> 122.8 | D14: =AVERAGE('India CPI Inflation -CSV'!D156:Q156) -> 132.57857 | E14: =AVERAGE('India CPI Inflation -CSV'!V156,'India CPI Inflation -CSV'!Y156) -> 117.85 | F14: Essential Svc Avg (Pre-COVID) | G14: =AVERAGE(E10:E12) -> 122.85
A15: 2022 | B15: March | C15: =AVERAGE('India CPI Inflation -CSV'!X157,'India CPI Inflation -CSV'!AB157) -> 125.6 | D15: =AVERAGE('India CPI Inflation -CSV'!D157:Q157) -> 133.12857 | E15: =AVERAGE('India CPI Inflation -CSV'!V157,'India CPI Inflation -CSV'!Y157) -> 123.2 | F15: Essential Svc Avg (Post-COVID) | G15: =AVERAGE(E13:E16) -> 123.8375
A16: 2023 | B16: March | C16: =AVERAGE('India CPI Inflation -CSV'!X158,'India CPI Inflation -CSV'!AB158) -> 127.55 | D16: =AVERAGE('India CPI Inflation -CSV'!D158:Q158) -> 133.78571 | E16: =AVERAGE('India CPI Inflation -CSV'!V158,'India CPI Inflation -CSV'!Y158) -> 127.2 | F16: Healthcare Change % | G16: =((AVERAGE(C13:C16)-AVERAGE(C10:C12))/AVERAGE(C10:C12))*100 -> 0.78093712
F17: Food Change % | G17: =((AVERAGE(D13:D16)-AVERAGE(D10:D12))/AVERAGE(D10:D12))*100 -> 0.13953738
A18: Healthcare- Only a marginal increase of 0.78% post-COVID, indicating stable healthcare cost indices in rural areas | F18: Essential Svc Change % | G18: =((AVERAGE(E13:E16)-AVERAGE(E10:E12))/AVERAGE(E10:E12))*100 -> 0.8038258
A19: Food- Minimal increase of 0.14%, suggesting effective supply chain management despite pandemic disruptions | F19: Peak Healthcare Year | G19: =INDEX(A10:A16,MATCH(MAX(C10:C16),C10:C16,0)) -> 2023
A20: Essential Service- 0.80% increase, likely due to increased fuel and transportation costs | F20: Peak Food Year | G20: =INDEX(A10:A16,MATCH(MAX(D10:D16),D10:D16,0)) -> 2023
F21: Peak Essential Svc Year | G21: =INDEX(A10:A16,MATCH(MAX(E10:E16),E10:E16,0)) -> 2023
A25: Urban
A26: Year | B26: Month | C26: Healthcare | D26: Food | E26: Essential Service(Tran&Comm) | F26: Metric | G26: Value
A27: 2017 | B27: March | C27: =AVERAGE('India CPI Inflation -CSV'!X153,'India CPI Inflation -CSV'!AB153) -> 122.4 | D27: =AVERAGE('India CPI Inflation -CSV'!D153:Q153) -> 132.37143 | E27: =AVERAGE('India CPI Inflation -CSV'!V153,'India CPI Inflation -CSV'!Y153) -> 118.2 | F27: Healthcare Avg (Pre-COVID 2017-2019) | G27: =AVERAGE(C27:C29) -> 124.98333
A28: 2018 | B28: March | C28: =AVERAGE('India CPI Inflation -CSV'!X154,'India CPI Inflation -CSV'!AB154) -> 125.2 | D28: =AVERAGE('India CPI Inflation -CSV'!D154:Q154) -> 133.14286 | E28: =AVERAGE('India CPI Inflation -CSV'!V154,'India CPI Inflation -CSV'!Y154) -> 123.35 | F28: Healthcare Avg (Post-COVID 2020-2023) | G28: =AVERAGE(C30:C33) -> 124.6875
A29: 2019 | B29: March | C29: =AVERAGE('India CPI Inflation -CSV'!X155,'India CPI Inflation -CSV'!AB155) -> 127.35 | D29: =AVERAGE('India CPI Inflation -CSV'!D155:Q155) -> 133.62143 | E29: =AVERAGE('India CPI Inflation -CSV'!V155,'India CPI Inflation -CSV'!Y155) -> 127.1 | F29: Food Avg (Pre-COVID 2017-2019) | G29: =AVERAGE(D27:D29) -> 133.04524
A30: 2020 | B30: March | C30: =AVERAGE('India CPI Inflation -CSV'!X156,'India CPI Inflation -CSV'!AB156) -> 122.8 | D30: =AVERAGE('India CPI Inflation -CSV'!D156:Q156) -> 132.57857 | E30: =AVERAGE('India CPI Inflation -CSV'!V156,'India CPI Inflation -CSV'!Y156) -> 117.85 | F30: Food Avg (Post-COVID 2020-2023) | G30: =AVERAGE(D30:D33) -> 133.05
A31: 2021 | B31: March | C31: =AVERAGE('India CPI Inflation -CSV'!X157,'India CPI Inflation -CSV'!AB157) -> 125.6 | D31: =AVERAGE('India CPI Inflation -CSV'!D157:Q157) -> 133.12857 | E31: =AVERAGE('India CPI Inflation -CSV'!V157,'India CPI Inflation -CSV'!Y157) -> 123.2 | F31: Essential Svc Avg (Pre-COVID) | G31: =AVERAGE(E27:E29) -> 122.88333
A32: 2022 | B32: March | C32: =AVERAGE('India CPI Inflation -CSV'!X158,'India CPI Inflation -CSV'!AB158) -> 127.55 | D32: =AVERAGE('India CPI Inflation -CSV'!D158:Q158) -> 133.78571 | E32: =AVERAGE('India CPI Inflation -CSV'!V158,'India CPI Inflation -CSV'!Y158) -> 127.2 | F32: Essential Svc Avg (Post-COVID) | G32: =AVERAGE(E30:E33) -> 121.3625
A33: 2023 | B33: March | C33: =AVERAGE('India CPI Inflation -CSV'!X159,'India CPI Inflation -CSV'!AB159) -> 122.8 | D33: =AVERAGE('India CPI Inflation -CSV'!D159:Q159) -> 132.70714 | E33: =AVERAGE('India CPI Inflation -CSV'!V159,'India CPI Inflation -CSV'!Y159) -> 117.2 | F33: Healthcare Change % | G33: =((AVERAGE(C30:C33)-AVERAGE(C27:C29))/AVERAGE(C27:C29))*100 -> -0.23669823
F34: Food Change % | G34: =((AVERAGE(D30:D33)-AVERAGE(D27:D29))/AVERAGE(D27:D29))*100 -> 0.0035791621
A35: HealthCare- Unusual -0.24% decline post-COVID, possibly due to increased digital health adoption and competition | F35: Essential Svc Change % | G35: =((AVERAGE(E30:E33)-AVERAGE(E27:E29))/AVERAGE(E27:E29))*100 -> -1.2376238
A36: Food- Near-zero change (0.004%), showing robust urban supply chains | F36: Peak Healthcare Year | G36: =INDEX(A27:A33,MATCH(MAX(C27:C33),C27:C33,0)) -> 2022
A37: Essential Service- Dropped significantly -1.24% decrease is notable, likely due to reduced travel demand during lockdowns and WFH culture | F37: Peak Food Year | G37: =INDEX(A27:A33,MATCH(MAX(D27:D33),D27:D33,0)) -> 2022
F38: Peak Essential Svc Year | G38: =INDEX(A27:A33,MATCH(MAX(E27:E33),E27:E33,0)) -> 2022
A42: Rural+Urban
A43: Year | B43: Month | C43: Healthcare | D43: Food | E43: Essential Service(Tran&Comm) | F43: Metric | G43: Value
A44: 2017 | B44: March | C44: =AVERAGE('India CPI Inflation -CSV'!X154,'India CPI Inflation -CSV'!AB154) -> 125.2 | D44: =AVERAGE('India CPI Inflation -CSV'!D154:Q154) -> 133.14286 | E44: =AVERAGE('India CPI Inflation -CSV'!V154,'India CPI Inflation -CSV'!Y154) -> 123.35 | F44: Healthcare Avg (Pre-COVID 2017-2019) | G44: =AVERAGE(C44:C46) -> 125.11667
A45: 2018 | B45: March | C45: =AVERAGE('India CPI Inflation -CSV'!X155,'India CPI Inflation -CSV'!AB155) -> 127.35 | D45: =AVERAGE('India CPI Inflation -CSV'!D155:Q155) -> 133.62143 | E45: =AVERAGE('India CPI Inflation -CSV'!V155,'India CPI Inflation -CSV'!Y155) -> 127.1 | F45: Healthcare Avg (Post-COVID 2020-2023) | G45: =AVERAGE(C47:C50) -> 125.4125
A46: 2019 | B46: March | C46: =AVERAGE('India CPI Inflation -CSV'!X156,'India CPI Inflation -CSV'!AB156) -> 122.8 | D46: =AVERAGE('India CPI Inflation -CSV'!D156:Q156) -> 132.57857 | E46: =AVERAGE('India CPI Inflation -CSV'!V156,'India CPI Inflation -CSV'!Y156) -> 117.85 | F46: Food Avg (Pre-COVID 2017-2019) | G46: =AVERAGE(D44:D46) -> 133.11429
A47: 2020 | B47: March | C47: =AVERAGE('India CPI Inflation -CSV'!X157,'India CPI Inflation -CSV'!AB157) -> 125.6 | D47: =AVERAGE('India CPI Inflation -CSV'!D157:Q157) -> 133.12857 | E47: =AVERAGE('India CPI Inflation -CSV'!V157,'India CPI Inflation -CSV'!Y157) -> 123.2 | F47: Food Avg (Post-COVID 2020-2023) | G47: =AVERAGE(D47:D50) -> 133.22321
A48: 2021 | B48: March | C48: =AVERAGE('India CPI Inflation -CSV'!X158,'India CPI Inflation -CSV'!AB158) -> 127.55 | D48: =AVERAGE('India CPI Inflation -CSV'!D158:Q158) -> 133.78571 | E48: =AVERAGE('India CPI Inflation -CSV'!V158,'India CPI Inflation -CSV'!Y158) -> 127.2 | F48: Essential Svc Avg (Pre-COVID) | G48: =AVERAGE(E44:E46) -> 122.76667
A49: 2022 | B49: March | C49: =AVERAGE('India CPI Inflation -CSV'!X159,'India CPI Inflation -CSV'!AB159) -> 122.8 | D49: =AVERAGE('India CPI Inflation -CSV'!D159:Q159) -> 132.70714 | E49: =AVERAGE('India CPI Inflation -CSV'!V159,'India CPI Inflation -CSV'!Y159) -> 117.2 | F49: Essential Svc Avg (Post-COVID) | G49: =AVERAGE(E47:E50) -> 122.6625
...

Sheet DA-5
A1: Trends in oil price change with change in inflation prices of all the categories
A2: \\Imported Crude oil data from PPAC site
A4: 2021 | B4: May
A5: 2023 | B5: May
C8: Rural | K8: Urban | S8: Rural+Urban
C9: Categories | K9: Categories | S9: Categories
A10: M-Y | B10: Imported Crude Oil price | C10: Food & beverages | D10: Clothing & Footwear | E10: Housing | F10: Health | G10: Transportation & Communcation | H10: Education | I10: Recreation & Misc | J10: General Index | K10: Food & beverages | L10: Clothing & Footwear | M10: Housing | N10: Health | O10: Transportation & Communcation | P10: Education | Q10: Recreation & Misc | R10: General Index | S10: Food & beverages | T10: Clothing & Footwear | U10: Housing | V10: Health | W10: Transportation & Communcation | X10: Education | Y10: Recreation & Misc | Z10: General Index
A11: 44287 | B11: 63.396977 | C11: 2236.3 | D11: 475.7 | E11: 294.62213 | F11: 319.9 | G11: 151.7 | H11: 164.1 | I11: 316.6 | J11: 157.6 | K11: 2284 | L11: 448.6 | M11: 309 | N11: 314.1 | O11: 142.1 | P11: 157.6 | Q11: 299.6 | R11: 158 | S11: 2252.9 | T11: 464.6 | U11: 313.2 | V11: 317.7 | W11: 146.6 | X11: 160.3 | Y11: 307.6 | Z11: 157.8
A12: 44317 | B12: 66.953085 | C12: 2284.9 | D12: 490.4 | E12: 297.92213 | F12: 328.4 | G12: 153.2 | H12: 167.6 | I12: 321.1 | J12: 161.1 | K12: 2322.9 | L12: 450.8 | M12: 311.7 | N12: 317.9 | O12: 145 | P12: 156.6 | Q12: 304.9 | R12: 159.5 | S12: 2297.6 | T12: 474.3 | U12: 316.3 | V12: 324.4 | W12: 148.9 | X12: 161.2 | Y12: 312.6 | Z12: 160.4
A13: 44348 | B13: 71.982647 | C13: 2311.7 | D13: 489.8 | E13: 298.32213 | F13: 329.1 | G13: 154.2 | H13: 166.8 | I13: 321.9 | J13: 162.1 | K13: 2349.8 | L13: 452.6 | M13: 310.3 | N13: 318.8 | O13: 147.5 | P13: 158.1 | Q13: 304.1 | R13: 160.4 | S13: 2324.7 | T13: 474.7 | U13: 315.3 | V13: 325.1 | W13: 150.7 | X13: 161.7 | Y13: 312.5 | Z13: 161.3
A14: 44378 | B14: 73.539061 | C14: 2322.1 | D14: 492.4 | E14: 299.42213 | F14: 330.8 | G14: 157.1 | H14: 167.2 | I14: 323.5 | J14: 163.2 | K14: 2367.3 | L14: 455.3 | M14: 312.2 | N14: 321.1 | O14: 149.5 | P14: 160.3 | Q14: 306.2 | R14: 161.8 | S14: 2338.2 | T14: 477.3 | U14: 317.3 | V14: 327.1 | W14: 153.1 | X14: 163.2 | Y14: 314.3 | Z14: 162.5
A15: 44409 | B15: 69.804724 | C15: 2321 | D15: 495.9 | E15: 300.02213 | F15: 331.4 | G15: 157.7 | H15: 167.5 | I15: 324.4 | J15: 163.6 | K15: 2354.4 | L15: 460.7 | M15: 315.3 | N15: 322.4 | O15: 150.4 | P15: 160.4 | Q15: 309.7 | R15: 162.3 | S15: 2334.1 | T15: 483 | U15: 319.6 | V15: 328.4 | W15: 154 | X15: 163.8 | Y15: 317.6 | Z15: 163.2
A16: 44440 | B16: 73.130738 | C16: 2324.1 | D16: 498.4 | E16: 300.42213 | F16: 332.1 | G16: 157.8 | H16: 168.5 | I16: 326.5 | J16: 164 | K16: 2354.4 | L16: 460.8 | M16: 315.4 | N16: 322.4 | O16: 150.5 | P16: 160.3 | Q16: 309.9 | R16: 162.3 | S16: 2334.1 | T16: 483.2 | U16: 319.6 | V16: 328.4 | W16: 154 | X16: 163.7 | Y16: 317.7 | Z16: 163.2
A17: 44470 | B17: 82.107394 | C17: 2355.4 | D17: 502 | E17: 301.12213 | F17: 333.6 | G17: 159.5 | H17: 169 | I17: 327.9 | J17: 166.3 | K17: 2395.4 | L17: 463.5 | M17: 317.9 | N17: 323.8 | O17: 152.2 | P17: 160.3 | Q17: 312.1 | R17: 164.6 | S17: 2368.2 | T17: 486.3 | U17: 322 | V17: 329.9 | W17: 155.7 | X17: 163.9 | Y17: 319.6 | Z17: 165.5
A18: 44501 | B18: 80.637301 | C18: 2373.4 | D18: 506.2 | E18: 302.02213 | F18: 335.8 | G18: 158.9 | H18: 169.3 | I18: 329 | J18: 167.6 | K18: 2414.9 | L18: 467.3 | M18: 319.4 | N18: 326 | O18: 151.2 | P18: 160.8 | Q18: 314 | R18: 165.6 | S18: 2387 | T18: 490.4 | U18: 323.5 | V18: 332.1 | W18: 154.8 | X18: 164.3 | Y18: 321.2 | Z18: 166.7
A19: 44531 | B19: 73.298824 | C19: 2359 | D19: 510.3 | E19: 303.02213 | F19: 336.8 | G19: 160.1 | H19: 169.7 | I19: 330.5 | J19: 167 | K19: 2403.1 | L19: 470.7 | M19: 319.4 | N19: 327.5 | O19: 151.8 | P19: 160.6 | Q19: 315.4 | R19: 165.2 | S19: 2373.3 | T19: 494.2 | U19: 323.6 | V19: 333.2 | W19: 155.7 | X19: 164.4 | Y19: 322.6 | Z19: 166.2
A20: 44562 | B20: 84.666319 | C20: 2343.7 | D20: 515.2 | E20: 304.02213 | F20: 337.9 | G20: 160.8 | H20: 169.9 | I20: 331.5 | J20: 166.4 | K20: 2383.1 | L20: 475.4 | M20: 321.3 | N20: 328.9 | O20: 152.7 | P20: 161 | Q20: 317 | R20: 165 | S20: 2356.4 | T20: 499.1 | U20: 325.6 | V20: 334.4 | W20: 156.5 | X20: 164.7 | Y20: 323.9 | Z20: 165.7
A21: 44593 | B21: 94.067715 | C21: 2341.9 | D21: 518.8 | E21: 304.82213 | F21: 339.8 | G21: 161.2 | H21: 170.3 | I21: 332.8 | J21: 166.7 | K21: 2380 | L21: 479.5 | M21: 322.9 | N21: 331.4 | O21: 153.1 | P21: 162 | Q21: 318.9 | R21: 165.5 | S21: 2354 | T21: 502.8 | U21: 327.3 | V21: 336.6 | W21: 156.9 | X21: 165.4 | Y21: 325.6 | Z21: 166.1
A22: 44621 | B22: 112.87479 | C22: 2371.4 | D22: 523.7 | E22: 305.62213 | F22: 343.4 | G22: 162 | H22: 170.6 | I22: 334.9 | J22: 168.7 | K22: 2393.8 | L22: 484.6 | M22: 323.9 | N22: 335 | O22: 154.2 | P22: 162.7 | Q22: 321.4 | R22: 166.5 | S22: 2377.9 | T22: 507.8 | U22: 328.1 | V22: 340.2 | W22: 157.9 | X22: 166 | Y22: 327.9 | Z22: 167.7
... A36: 45047 | B36: 74.981548 | C36: 2490.6 | D36: 569.9 | E36: 318.92213 | F36: 372.7 | G36: 169.7 | H36: 180.3 | I36: 353.3 | J36: 179.8 | K36: 2539.3 | L36: 528.7 | M36: 345.7 | N36: 367.8 | O36: 160.4 | P36: 174.8 | Q36: 340.8 | R36: 178.2 | S36: 2507.9 | T36: 553.2 | U36: 350.8 | V36: 370.9 | W36: 164.8 | X36: 177.1 | Y36: 346.9 | Z36: 179.1
A39: \\Correlating each category with Crude oil from different sectors to know the affect.
C41: Food & beverages | D41: Clothing & Footwear | E41: Housing | F41: Health | G41: Transportation & Communcation | H41: Education | I41: Recreation & Misc | J41: General Index | K41: Food & beverages | L41: Clothing & Footwear | M41: Housing | N41: Health | O41: Transportation & Communcation | P41: Education | Q41: Recreation & Misc | R41: General Index | S41: Food & beverages | T41: Clothing & Footwear | U41: Housing | V41: Health | W41: Transportation & Communcation | X41: Education | Y41: Recreation & Misc | Z41: General Index
A42: Correl | C42: =CORREL($B$11:$B$36,C11:C36) -> 0.42042572 | D42: =CORREL($B$11:$B$36,D11:D36) -> 0.37456852 | E42: =CORREL($B$11:$B$36,E11:E36) -> 0.30660102 | F42: =CORREL($B$11:$B$36,F11:F36) -> 0.25376357 | G42: =CORREL($B$11:$B$36,G11:G36) -> 0.4964643 | H42: =CORREL($B$11:$B$36,H11:H36) -> 0.24735977 | I42: =CORREL($B$11:$B$36,I11:I36) -> 0.35143093 | J42: =CORREL($B$11:$B$36,J11:J36) -> 0.39312305 | ... Z42: =CORREL($B$11:$B$36,Z11:Z36) -> 0.38680786
C43: Rural | K43: Urban | S43: Rural+Urban
A45: In all sectors, Transportation & Comm had the highest affect with change in crude oil prices
