Workbook

Sheet Music_Festival_Data
A1: Festival_Name | B1: City | C1: Date | D1: Tour_Name | E1: Headlining_Artist | F1: Supporting_Artists | G1: Ticket_Price(Rs) | H1: Total_Attendance | I1: Merchandise_Sales (Rs) | J1: Outlier_Flag_for_Merchandise_Sales | K1: Sponsorship_Revenue (Rs) | L1: Outlier_Flag_for_Sponsorship_Revenue | M1: Total_Revenue (Rs) | N1: Data_Validation_Status
A2: NH7 Pune | B2: Kolkata | C2: 45303 | E2: Badshah | F2: DJ Snake, Honey Singh | G2: 1253 | H2: 6166 | I2: 1942290 | J2: =IF(OR(I2>'Missing Values & Outliers'!$K$8,I2<'Missing Values & Outliers'!$K$9),"O","NA") -> NA | K2: 3680408 | L2: =IF(OR(K2>'Missing Values & Outliers'!$K$15,K2<'Missing Values & Outliers'!$K$16),"O","NA") -> NA | M2: 13348696 | N2: Valid
A3: Ziro Festival Arunachal | B3: Delhi | C3: 45403 | E3: Honey Singh | F3: Bryan Adams, Martin Garrix, Mika Singh | G3: 1689 | H3: 40643 | I3: 16622987 | J3: =IF(OR(I3>'Missing Values & Outliers'!$K$8,I3<'Missing Values & Outliers'!$K$9),"O","NA") -> O | K3: 2589481 | L3: =IF(OR(K3>'Missing Values & Outliers'!$K$15,K3<'Missing Values & Outliers'!$K$16),"O","NA") -> NA | M3: 87858495 | N3: Valid
A4: NH7 Pune | B4: Bengaluru | C4: 45553 | D4: Classics Tour | E4: Bryan Adams | F4: Badshah, Arijit Singh, Martin Garrix, Diljit Dosanjh | G4: 6813.8 | H4: 17889.9 | I4: 7667100 | J4: =IF(OR(I4>'Missing Values & Outliers'!$K$8,I4<'Missing Values & Outliers'!$K$9),"O","NA") -> NA | K4: 640053 | L4: =IF(OR(K4>'Missing Values & Outliers'!$K$15,K4<'Missing Values & Outliers'!$K$16),"O","NA") -> NA | M4: 132693072 | N4: Valid
A5: VH1 Supersonic Delhi | B5: Goa | C5: 45353 | E5: Honey Singh | F5: Martin Garrix, Badshah, Ed Sheeran, Diljit Dosanjh | G5: 2144 | H5: 14688 | I5: 2350080 | J5: =IF(OR(I5>'Missing Values & Outliers'!$K$8,I5<'Missing Values & Outliers'!$K$9),"O","NA") -> NA | K5: 2712686 | L5: =IF(OR(K5>'Missing Values & Outliers'!$K$15,K5<'Missing Values & Outliers'!$K$16),"O","NA") -> NA | M5: 36553838 | N5: Valid
A6: Hornbill Festival Nagaland | B6: Nagpur | C6: 45454 | D6: Soulful Nights Tour | E6: Arijit Singh | F6: Martin Garrix, Badshah | G6: 1886 | H6: 35244 | I6: 6132456 | J6: =IF(OR(I6>'Missing Values & Outliers'!$K$8,I6<'Missing Values & Outliers'!$K$9),"O","NA") -> NA | K6: 1181193 | L6: =IF(OR(K6>'Missing Values & Outliers'!$K$15,K6<'Missing Values & Outliers'!$K$16),"O","NA") -> NA | M6: 73783833 | N6: Valid
A7: Ziro Festival Arunachal | B7: Jaipur | C7: 45437 | E7: Mika Singh | F7: Diljit Dosanjh, Mika Singh | G7: 3984 | H7: ='Missing Values & Outliers'!$E$13 -> 20798.88 | I7: 2252122 | J7: =IF(OR(I7>'Missing Values & Outliers'!$K$8,I7<'Missing Values & Outliers'!$K$9),"O","NA") -> NA | K7: 2302603 | L7: =IF(OR(K7>'Missing Values & Outliers'!$K$15,K7<'Missing Values & Outliers'!$K$16),"O","NA") -> NA | M7: 58605653 | N7: Valid
A8: Ziro Festival Arunachal | B8: Goa | C8: 45371 | D8: Classics Tour | E8: Bryan Adams | F8: Ed Sheeran, Mika Singh, Shreya Ghoshal, Bryan Adams | G8: ='Missing Values & Outliers'!$E$5 -> 2910.2168 | H8: 18778.2 | I8: 4828680 | J8: =IF(OR(I8>'Missing Values & Outliers'!$K$8,I8<'Missing Values & Outliers'!$K$9),"O","NA") -> NA | K8: 4948076 | L8: =IF(OR(K8>'Missing Values & Outliers'!$K$15,K8<'Missing Values & Outliers'!$K$16),"O","NA") -> NA | M8: 111635078 | N8: Valid
A9: NH7 Pune | B9: Nagpur | C9: 45462 | E9: Badshah | F9: Honey Singh, Badshah, Bryan Adams, Martin Garrix | G9: 840 | H9: 33535 | I9: 12206740 | J9: =IF(OR(I9>'Missing Values & Outliers'!$K$8,I9<'Missing Values & Outliers'!$K$9),"O","NA") -> NA | K9: 1201595 | L9: =IF(OR(K9>'Missing Values & Outliers'!$K$15,K9<'Missing Values & Outliers'!$K$16),"O","NA") -> NA | M9: 41577735 | N9: Valid
A10: Bollywood Music Project | B10: Delhi | C10: 45440 | E10: Shreya Ghoshal | F10: Ed Sheeran, Shreya Ghoshal, Bryan Adams, Badshah | G10: 4191 | H10: ='Missing Values & Outliers'!$E$13 -> 20798.88 | I10: 4279770 | J10: =IF(OR(I10>'Missing Values & Outliers'!$K$8,I10<'Missing Values & Outliers'!$K$9),"O","NA") -> NA | K10: 3427104 | L10: =IF(OR(K10>'Missing Values & Outliers'!$K$15,K10<'Missing Values & Outliers'!$K$16),"O","NA") -> NA | M10: 81824709 | N10: Valid
A11: Lollapalooza Mumbai | B11: Kolkata | C11: 45319 | E11: Honey Singh | F11: Honey Singh, Diljit Dosanjh | G11: 1823 | H11: 15513 | I11: 7539318 | J11: =IF(OR(I11>'Missing Values & Outliers'!$K$8,I11<'Missing Values & Outliers'!$K$9),"O","NA") -> NA | K11: 3948781 | L11: =IF(OR(K11>'Missing Values & Outliers'!$K$15,K11<'Missing Values & Outliers'!$K$16),"O","NA") -> NA | M11: 39768298 | N11: Valid
A12: Hornbill Festival Nagaland | B12: Jaipur | C12: 45462 | E12: DJ Snake | F12: Honey Singh, Diljit Dosanjh, Arijit Singh | G12: 3953.6 | H12: 21693 | I12: 9306297 | J12: =IF(OR(I12>'Missing Values & Outliers'!$K$8,I12<'Missing Values & Outliers'!$K$9),"O","NA") -> NA | K12: 4798020 | L12: =IF(OR(K12>'Missing Values & Outliers'!$K$15,K12<'Missing Values & Outliers'!$K$16),"O","NA") -> NA | M12: 75365349 | N12: Valid
A13: Sunburn Goa | B13: Goa | C13: 45649 | E13: Shreya Ghoshal | F13: Honey Singh, Badshah, Bryan Adams | G13: 2842 | H13: 24021 | I13: 5020389 | J13: =IF(OR(I13>'Missing Values & Outliers'!$K$8,I13<'Missing Values & Outliers'!$K$9),"O","NA") -> NA | K13: 2851905 | L13: =IF(OR(K13>'Missing Values & Outliers'!$K$15,K13<'Missing Values & Outliers'!$K$16),"O","NA") -> NA | M13: 76139976 | N13: Valid
A14: Supersonic Bengaluru | B14: Pune | C14: 45428 | D14: Born To Shine Tour | E14: Diljit Dosanjh | F14: Mika Singh, Ed Sheeran, Arijit Singh | G14: 528 | H14: 33241 | I14: 2659280 | J14: =IF(OR(I14>'Missing Values & Outliers'!$K$8,I14<'Missing Values & Outliers'!$K$9),"O","NA") -> NA | K14: 3167786 | L14: =IF(OR(K14>'Missing Values & Outliers'!$K$15,K14<'Missing Values & Outliers'!$K$16),"O","NA") -> NA | M14: 19328026 | N14: Valid
A15: Magnetic Fields Rajasthan | B15: Mumbai | C15: 45644 | E15: Martin Garrix | F15: Shreya Ghoshal, Ed Sheeran, Arijit Singh | G15: 1543 | H15: 19867 | I15: 2821114 | J15: =IF(OR(I15>'Missing Values & Outliers'!$K$8,I15<'Missing Values & Outliers'!$K$9),"O","NA") -> NA | K15: 2897760 | L15: =IF(OR(K15>'Missing Values & Outliers'!$K$15,K15<'Missing Values & Outliers'!$K$16),"O","NA") -> NA | M15: 36373655 | N15: Valid
A16: Hornbill Festival Nagaland | B16: Amritsar | C16: 45344 | E16: Shreya Ghoshal | F16: Bryan Adams, Badshah, Honey Singh | G16: 2188 | H16: 20603 | I16: 9559792 | J16: =IF(OR(I16>'Missing Values & Outliers'!$K$8,I16<'Missing Values & Outliers'!$K$9),"O","NA") -> NA | K16: 4600450 | L16: =IF(OR(K16>'Missing Values & Outliers'!$K$15,K16<'Missing Values & Outliers'!$K$16),"O","NA") -> NA | M16: 59239606 | N16: Valid
A17: VH1 Supersonic Delhi | B17: Kolkata | C17: 45581 | D17: Classics Tour | E17: Bryan Adams | F17: Ed Sheeran, Shreya Ghoshal | G17: 2217.6 | H17: 9504.6 | I17: 5892852 | J17: =IF(OR(I17>'Missing Values & Outliers'!$K$8,I17<'Missing Values & Outliers'!$K$9),"O","NA") -> NA | K17: 795307 | L17: =IF(OR(K17>'Missing Values & Outliers'!$K$15,K17<'Missing Values & Outliers'!$K$16),"O","NA") -> NA | M17: 28195711 | N17: Valid
A18: Lollapalooza Mumbai | B18: Delhi | C18: 45455 | D18: Classics Tour | E18: Bryan Adams | F18: Martin Garrix, Mika Singh, Bryan Adams | G18: 5397 | H18: 9158.1 | I18: 1687707 | J18: =IF(OR(I18>'Missing Values & Outliers'!$K$8,I18<'Missing Values & Outliers'!$K$9),"O","NA") -> NA | K18: 2188470 | L18: =IF(OR(K18>'Missing Values & Outliers'!$K$15,K18<'Missing Values & Outliers'!$K$16),"O","NA") -> NA | M18: 54311142 | N18: Valid
A19: Ziro Festival Arunachal | B19: Pune | C19: 45384 | D19: Mathematics Tour | E19: Ed Sheeran | F19: Honey Singh, Ed Sheeran | G19: 1601.6 | H19: 11790 | I19: 3030030 | J19: =IF(OR(I19>'Missing Values & Outliers'!$K$8,I19<'Missing Values & Outliers'!$K$9),"O","NA") -> NA | K19: 3635278 | L19: =IF(OR(K19>'Missing Values & Outliers'!$K$15,K19<'Missing Values & Outliers'!$K$16),"O","NA") -> NA | M19: 20153068 | N19: Valid
A20: Ziro Festival Arunachal | B20: Delhi | C20: 45531 | E20: Shreya Ghoshal | F20: Honey Singh, Mika Singh, Martin Garrix, Ed Sheeran | G20: 4564 | H20: 31755 | I20: 6890835 | J20: =IF(OR(I20>'Missing Values & Outliers'!$K$8,I20<'Missing Values & Outliers'!$K$9),"O","NA") -> NA | K20: 4732974 | L20: =IF(OR(K20>'Missing Values & Outliers'!$K$15,K20<'Missing Values & Outliers'!$K$16),"O","NA") -> NA | M20: 156553629 | N20: Valid
A21: Sunburn Goa | B21: Nagpur | C21: 45634 | D21: Classics Tour | E21: Bryan Adams | F21: Ed Sheeran, Mika Singh, Shreya Ghoshal, Honey Singh | G21: 3350.2 | H21: 2975.7 | I21: 1041495 | J21: =IF(OR(I21>'Missing Values & Outliers'!$K$8,I21<'Missing Values & Outliers'!$K$9),"O","NA") -> NA | K21: 3001940 | L21: =IF(OR(K21>'Missing Values & Outliers'!$K$15,K21<'Missing Values & Outliers'!$K$16),"O","NA") -> NA | M21: 14216078 | N21: Valid
A22: Sunburn Goa | B22: Delhi | C22: 45460 | E22: Badshah | F22: Shreya Ghoshal, Diljit Dosanjh, Arijit Singh | G22: 4045 | H22: 27719 | I22: 7539568 | J22: =IF(OR(I22>'Missing Values & Outliers'!$K$8,I22<'Missing Values & Outliers'!$K$9),"O","NA") -> NA | K22: 4670910 | L22: =IF(OR(K22>'Missing Values & Outliers'!$K$15,K22<'Missing Values & Outliers'!$K$16),"O","NA") -> NA | M22: 124333833 | N22: Valid
A23: Sunburn Goa | B23: Bengaluru | C23: 45425 | D23: Soulful Nights Tour | E23: Arijit Singh | F23: Honey Singh, Diljit Dosanjh, Badshah | G23: 1008 | H23: 21142 | I23: 2558182 | J23: =IF(OR(I23>'Missing Values & Outliers'!$K$8,I23<'Missing Values & Outliers'!$K$9),"O","NA") -> NA | K23: 1632574 | L23: =IF(OR(K23>'Missing Values & Outliers'!$K$15,K23<'Missing Values & Outliers'!$K$16),"O","NA") -> NA | M23: 25501892 | N23: Valid
A24: NH7 Pune | B24: Chandigarh | C24: 45474 | E24: Martin Garrix | F24: Honey Singh, Bryan Adams, DJ Snake | G24: 2334 | H24: 16842 | I24: 6905220 | J24: =IF(OR(I24>'Missing Values & Outliers'!$K$8,I24<'Missing Values & Outliers'!$K$9),"O","NA") -> NA | K24: 1067015 | L24: =IF(OR(K24>'Missing Values & Outliers'!$K$15,K24<'Missing Values & Outliers'!$K$16),"O","NA") -> NA | M24: 47281463 | N24: Valid
A25: Goa Tribal Festival | B25: Delhi | C25: 45299 | D25: Born To Shine Tour | E25: Diljit Dosanjh | F25: Ed Sheeran, Diljit Dosanjh, Shreya Ghoshal, Badshah | G25: ='Missing Values & Outliers'!$E$5 -> 2910.2168 | H25: 14456 | I25: 4603680 | J25: =IF(OR(I25>'Missing Values & Outliers'!$K$8,I25<'Missing Values & Outliers'!$K$9),"O","NA") -> NA | K25: 2403962 | L25: =IF(OR(K25>'Missing Values & Outliers'!$K$15,K25<'Missing Values & Outliers'!$K$16),"O","NA") -> NA | M25: 41090442 | N25: Valid
A26: Magnetic Fields Rajasthan | B26: Amritsar | C26: 45416 | E26: Badshah | F26: Mika Singh, Diljit Dosanjh, Martin Garrix | G26: 3977 | H26: 25243 | I26: 9238938 | J26: =IF(OR(I26>'Missing Values & Outliers'!$K$8,I26<'Missing Values & Outliers'!$K$9),"O","NA") -> NA | K26: 4689343 | L26: =IF(OR(K26>'Missing Values & Outliers'!$K$15,K26<'Missing Values & Outliers'!$K$16),"O","NA") -> NA | M26: 114319692 | N26: Valid
A27: Sunburn Goa | B27: Jaipur | C27: 45407 | E27: Honey Singh | F27: Bryan Adams, Diljit Dosanjh, Honey Singh, Mika Singh | G27: 3449 | H27: 13539 | I27: 5672841 | J27: =IF(OR(I27>'Missing Values & Outliers'!$K$8,I27<'Missing Values & Outliers'!$K$9),"O","NA") -> NA | K27: 3471436 | L27: =IF(OR(K27>'Missing Values & Outliers'!$K$15,K27<'Missing Values & Outliers'!$K$16),"O","NA") -> NA | M27: 55840288 | N27: Valid
A28: Hornbill Festival Nagaland | B28: Pune | C28: 45316 | E28: Badshah | F28: Martin Garrix, Bryan Adams, DJ Snake | G28: 3668 | H28: 36462 | I28: 5250528 | J28: =IF(OR(I28>'Missing Values & Outliers'!$K$8,I28<'Missing Values & Outliers'!$K$9),"O","NA") -> NA | K28: 2377592 | L28: =IF(OR(K28>'Missing Values & Outliers'!$K$15,K28<'Missing Values & Outliers'!$K$16),"O","NA") -> NA | M28: 141370736 | N28: Valid
A29: NH7 Pune | B29: Goa | C29: 45539 | E29: Badshah | F29: Arijit Singh, Diljit Dosanjh | G29: 3279 | H29: 32540 | I29: 13341400 | J29: =IF(OR(I29>'Missing Values & Outliers'!$K$8,I29<'Missing Values & Outliers'!$K$9),"O","NA") -> NA | K29: 2840750 | L29: =IF(OR(K29>'Missing Values & Outliers'!$K$15,K29<'Missing Values & Outliers'!$K$16),"O","NA") -> NA | M29: 122880810 | N29: Valid
A30: NH7 Pune | B30: Amritsar | C30: 45639 | E30: Honey Singh | F30: Diljit Dosanjh, Honey Singh, DJ Snake, Shreya Ghoshal | G30: 2948 | H30: 9316 | I30: 1266976 | J30: =IF(OR(I30>'Missing Values & Outliers'!$K$8,I30<'Missing Values & Outliers'!$K$9),"O","NA") -> NA | K30: 2704822 | L30: =IF(OR(K30>'Missing Values & Outliers'!$K$15,K30<'Missing Values & Outliers'!$K$16),"O","NA") -> NA | M30: 31435366 | N30: Valid
A31: NH7 Pune | B31: Delhi | C31: 45647 | E31: DJ Snake | F31: Bryan Adams, Mika Singh, Arijit Singh | G31: 2749.6 | H31: 17172 | I31: 7830432 | J31: =IF(OR(I31>'Missing Values & Outliers'!$K$8,I31<'Missing Values & Outliers'!$K$9),"O","NA") -> NA | K31: 3956927 | L31: =IF(OR(K31>'Missing Values & Outliers'!$K$15,K31<'Missing Values & Outliers'!$K$16),"O","NA") -> NA | M31: 45513167 | N31: Valid
A32: Ziro Festival Arunachal | B32: Bengaluru | C32: 45410 | E32: Honey Singh | F32: Arijit Singh, Honey Singh | G32: ='Missing Values & Outliers'!$E$5 -> 2910.2168 | H32: 16737 | I32: 6276375 | J32: =IF(OR(I32>'Missing Values & Outliers'!$K$8,I32<'Missing Values & Outliers'!$K$9),"O","NA") -> NA | K32: 2726932 | L32: =IF(OR(K32>'Missing Values & Outliers'!$K$15,K32<'Missing Values & Outliers'!$K$16),"O","NA") -> NA | M32: 85424449 | N32: Valid
A33: NH7 Pune | B33: Chandigarh | C33: 45392 | E33: Shreya Ghoshal | F33: Martin Garrix, Diljit Dosanjh, Badshah, Mika Singh | G33: 632 | H33: 35304 | I33: 10379376 | J33: =IF(OR(I33>'Missing Values & Outliers'!$K$8,I33<'Missing Values & Outliers'!$K$9),"O","NA") -> NA | K33: 1590737 | L33: =IF(OR(K33>'Missing Values & Outliers'!$K$15,K33<'Missing Values & Outliers'!$K$16),"O","NA") -> NA | M33: 34282241 | N33: Valid
A34: Goa Tribal Festival | B34: Kolkata | C34: 45360 | E34: Honey Singh | F34: DJ Snake, Arijit Singh, Badshah, Mika Singh | G34: 1932 | H34: 16841 | I34: 7713178 | J34: =IF(OR(I34>'Missing Values & Outliers'!$K$8,I34<'Missing Values & Outliers'!$K$9),"O","NA") -> NA | K34: 4738764 | L34: =IF(OR(K34>'Missing Values & Outliers'!$K$15,K34<'Missing Values & Outliers'!$K$16),"O","NA") -> NA | M34: 44988754 | N34: Valid
A35: Ziro Festival Arunachal | B35: Goa | C35: 45358 | D35: Classics Tour | E35: Bryan Adams | F35: Mika Singh, Diljit Dosanjh, Shreya Ghoshal | G35: 1598.8 | H35: 18210.5 | I35: 7336230 | J35: =IF(OR(I35>'Missing Values & Outliers'!$K$8,I35<'Missing Values & Outliers'!$K$9),"O","NA") -> NA | K35: 2229062 | L35: =IF(OR(K35>'Missing Values & Outliers'!$K$15,K35<'Missing Values & Outliers'!$K$16),"O","NA") -> NA | M35: 39274422 | N35: Valid
A36: NH7 Pune | B36: Delhi | C36: 45326 | D36: Born To Shine Tour | E36: Diljit Dosanjh | F36: Mika Singh, Ed Sheeran, Honey Singh, Diljit Dosanjh | G36: 1933 | H36: 58687.2 | I36: 16296984 | J36: =IF(OR(I36>'Missing Values & Outliers'!$K$8,I36<'Missing Values & Outliers'!$K$9),"O","NA") -> O | K36: 1120895 | L36: =IF(OR(K36>'Missing Values & Outliers'!$K$15,K36<'Missing Values & Outliers'!$K$16),"O","NA") -> NA | M36: 104681231 | N36: Valid
A37: Lollapalooza Mumbai | B37: Bengaluru | C37: 45395 | D37: Born To Shine Tour | E37: Diljit Dosanjh | F37: Diljit Dosanjh, DJ Snake, Honey Singh, Shreya Ghoshal | G37: ='Missing Values & Outliers'!$E$5 -> 2910.2168 | H37: 7559.5 | I37: 1913135 | J37: =IF(OR(I37>'Missing Values & Outliers'!$K$8,I37<'Missing Values & Outliers'!$K$9),"O","NA") -> NA | K37: 4680189 | L37: =IF(OR(K37>'Missing Values & Outliers'!$K$15,K37<'Missing Values & Outliers'!$K$16),"O","NA") -> NA | M37: 21654174 | N37: Valid
A38: VH1 Supersonic Delhi | B38: Bengaluru | C38: 45509 | E38: Martin Garrix | F38: DJ Snake, Honey Singh, Diljit Dosanjh | G38: 4452 | H38: 31745 | I38: 4412555 | J38: =IF(OR(I38>'Missing Values & Outliers'!$K$8,I38<'Missing Values & Outliers'!$K$9),"O","NA") -> NA | K38: 4091720 | L38: =IF(OR(K38>'Missing Values & Outliers'!$K$15,K38<'Missing Values & Outliers'!$K$16),"O","NA") -> NA | M38: 149833015 | N38: Valid
A39: Bollywood Music Project | B39: Mumbai | C39: 45555 | E39: Mika Singh | F39: Arijit Singh, DJ Snake, Martin Garrix | G39: 2716 | H39: 12688 | I39: 2486848 | J39: =IF(OR(I39>'Missing Values & Outliers'!$K$8,I39<'Missing Values & Outliers'!$K$9),"O","NA") -> NA | K39: 1413822 | L39: =IF(OR(K39>'Missing Values & Outliers'!$K$15,K39<'Missing Values & Outliers'!$K$16),"O","NA") -> NA | M39: 38361278 | N39: Valid
A40: Sunburn Goa | B40: Chandigarh | C40: 45507 | E40: Mika Singh | F40: DJ Snake, Badshah | G40: 2237 | H40: 20276 | I40: 9671652 | J40: =IF(OR(I40>'Missing Values & Outliers'!$K$8,I40<'Missing Values & Outliers'!$K$9),"O","NA") -> NA | K40: 4912334 | L40: =IF(OR(K40>'Missing Values & Outliers'!$K$15,K40<'Missing Values & Outliers'!$K$16),"O","NA") -> NA | M40: 59941398 | N40: Valid
...

Sheet Artist_Popularity_Data
A1: Artist_Name | B1: Genre | C1: Average_Ticket_Price | D1: Average_Attendance_Per_City | E1: Social_Media_Followers (millions) | F1: Streaming_Plays (millions) | G1: Merchandise_Revenue_Per_Concert (Rs) | H1: Tour_Impact | I1: Cities_Performed_In
A2: Diljit Dosanjh | B2: Punjabi | C2: 2027 | D2: 33738 | E2: 46 | F2: 116 | G2: 22334556 | H2: Yes | I2: Amritsar, Kolkata, Delhi, Mumbai, Bengaluru
A3: Honey Singh | B3: Hip-Hop | C3: 1573 | D3: 35223 | E3: 34 | F3: 430 | G3: 25360560 | H3: No | I3: Pune, Amritsar, Bengaluru
A4: Mika Singh | B4: Bollywood | C4: 1025 | D4: 11057 | E4: 12 | F4: 371 | G4: 7983154 | H4: No | I4: Delhi, Amritsar, Bengaluru, Mumbai
A5: Arijit Singh | B5: Bollywood | C5: 2437 | D5: 25729 | E5: 30 | F5: 584 | G5: 18730712 | H5: Yes | I5: Nagpur, Jaipur, Chandigarh
A6: Ed Sheeran | B6: International Pop | C6: 3436 | D6: 18609 | E6: 55 | F6: 736 | G6: 4856949 | H6: Yes | I6: Pune, Amritsar, Goa, Chandigarh
A7: Bryan Adams | B7: Rock | C7: 992 | D7: 21632.556 | E7: 30 | F7: 81 | G7: 8678356 | H7: Yes | I7: Delhi, Jaipur, Bengaluru, Mumbai
A8: DJ Snake | B8: EDM | C8: 1431 | D8: 19089 | E8: 32 | F8: 429 | G8: 10193526 | H8: No | I8: Bengaluru, Jaipur, Mumbai, Chandigarh, Kolkata, Delhi
A9: Martin Garrix | B9: EDM | C9: 2499 | D9: 11603 | E9: 43 | F9: 298 | G9: 6462871 | H9: No | I9: Chandigarh, Delhi, Pune, Nagpur, Bengaluru, Kolkata
A10: Badshah | B10: Bollywood | C10: 3351 | D10: 36448 | E10: 33 | F10: 483 | G10: 20228640 | H10: No | I10: Nagpur, Goa, Amritsar, Chandigarh, Mumbai
A11: Shreya Ghoshal | B11: Classical/Bollywood | C11: 3326 | D11: 3197 | E11: 23 | F11: 271 | G11: 792856 | H11: No | I11: Pune, Mumbai, Delhi, Bengaluru, Amritsar

Sheet Missing Values & Outliers
A1: Missing Values | G1: Outlier
A2: Ticket_Price(Rs) | B2: Total_Attendance | G2: Merchandise_Sales (Rs) | H2: Sponsorship_Revenue (Rs) | P2: Festival_Name | Q2: City | R2: Date | S2: Tour_Name | T2: Headlining_Artist | U2: Supporting_Artists | V2: Ticket_Price(Rs) | W2: Total_Attendance | X2: Merchandise_Sales (Rs) | Y2: Sponsorship_Revenue (Rs) | Z2: Total_Revenue (Rs)
A3: 1253 | B3: 6166 | G3: 1942290 | H3: 3680408 | O3: blank counts | P3: =COUNTBLANK(Music_Festival_Data!A2:A106) -> 0 | Q3: =COUNTBLANK(Music_Festival_Data!B2:B106) -> 0 | R3: =COUNTBLANK(Music_Festival_Data!C2:C106) -> 0 | S3: =COUNTBLANK(Music_Festival_Data!D2:D106) -> 63 | T3: =COUNTBLANK(Music_Festival_Data!E2:E106) -> 0 | U3: =COUNTBLANK(Music_Festival_Data!F2:F106) -> 0 | V3: =COUNTBLANK(Music_Festival_Data!G2:G106) -> 0 | W3: =COUNTBLANK(Music_Festival_Data!H2:H106) -> 0 | X3: =COUNTBLANK(Music_Festival_Data!I2:I106) -> 0 | Y3: =COUNTBLANK(Music_Festival_Data!K2:K106) -> 0 | Z3: =COUNTBLANK(Music_Festival_Data!M2:M106) -> 0
A4: 1689 | B4: 40643 | D4: Ticket Price | G4: 16622987 | H4: 2589481 | J4: Merchandise_Sales (Rs) | O4: outlier | X4: =COUNTIF(Music_Festival_Data!J2:J106,"O") -> 6 | Y4: =COUNTIF(Music_Festival_Data!L2:L106,"O") -> 2
A5: 6813.8 | B5: 17889.9 | D5: average | E5: =AVERAGE($A$3:$A$107) -> 2910.2168 | G5: 7667100 | H5: 640053 | J5: Q1 | K5: =QUARTILE($G$3:$G$107,1) -> 2722125 | O5: Outliers have been removed
A6: 2144 | B6: 14688 | D6: std | E6: =STDEV(A3:A107) -> 1468.7673 | G6: 2350080 | H6: 2712686 | J6: Q3 | K6: =QUARTILE($G$3:$G$107,3) -> 7713178
A7: 1886 | B7: 35244 | D7: std% | E7: =E6/E5*100 -> 50.469341 | G7: 6132456 | H7: 1181193 | J7: IQR | K7: =K6-K5 -> 4991053
A8: 3984 | G8: 2252122 | H8: 2302603 | J8: UL | K8: =K6+(1.5*K7) -> 15199758 | O8: International vs Local Artists
B9: 18778.2 | D9: But in problem statement it | G9: 4828680 | H9: 4948076 | J9: LL | K9: =K5-(1.5*K7) -> -4764454.5 | O9: Artists | P9: International & Local Artists
A10: 840 | B10: 33535 | D10: is asked to fill | G10: 12206740 | H10: 1201595 | O10: Badshah | P10: Local Artist
A11: 4191 | D11: missing values with mean | G11: 4279770 | H11: 3427104 | J11: Sponsorship_Revenue (Rs) | O11: Bryan Adams | P11: International
A12: 1823 | B12: 15513 | D12: Total Attendance | G12: 7539318 | H12: 3948781 | J12: Q1 | K12: =QUARTILE($H$3:$H$107,1) -> 1719569 | O12: Honey Singh | P12: Local Artist
A13: 3953.6 | B13: 21693 | D13: average | E13: =AVERAGE($B$3:$B$107) -> 20798.88 | G13: 9306297 | H13: 4798020 | J13: Q3 | K13: =QUARTILE($H$3:$H$107,3) -> 3956927 | O13: Arijit Singh | P13: Local Artist
A14: 2842 | B14: 24021 | D14: std | E14: =STDEV($B$3:$B$107) -> 12539.172 | G14: 5020389 | H14: 2851905 | J14: IQR | K14: =K13-K12 -> 2237358 | O14: Mika Singh | P14: Local Artist
A15: 528 | B15: 33241 | D15: std% | E15: =E14/E13*100 -> 60.287729 | G15: 2659280 | H15: 3167786 | J15: UL | K15: =K13+(1.5*K14) -> 7312964 | O15: Shreya Ghoshal | P15: Local Artist
A16: 1543 | B16: 19867 | G16: 2821114 | H16: 2897760 | J16: LL | K16: =K12-(1.5*K14) -> -1636468 | O16: DJ Snake | P16: International
A17: 2188 | B17: 20603 | G17: 9559792 | H17: 4600450 | O17: Diljit Dosanjh | P17: Local Artist
A18: 2217.6 | B18: 9504.6 | G18: 5892852 | H18: 795307 | O18: Martin Garrix | P18: International
A19: 5397 | B19: 9158.1 | G19: 1687707 | H19: 2188470 | O19: Ed Sheeran | P19: International
A20: 1601.6 | B20: 11790 | G20: 3030030 | H20: 3635278
A21: 4564 | B21: 31755 | G21: 6890835 | H21: 4732974
A22: 3350.2 | B22: 2975.7 | G22: 1041495 | H22: 3001940
A23: 4045 | B23: 27719 | G23: 7539568 | H23: 4670910
A24: 1008 | B24: 21142 | G24: 2558182 | H24: 1632574
A25: 2334 | B25: 16842 | G25: 6905220 | H25: 1067015
B26: 14456 | G26: 4603680 | H26: 2403962
A27: 3977 | B27: 25243 | G27: 9238938 | H27: 4689343
A28: 3449 | B28: 13539 | G28: 5672841 | H28: 3471436
A29: 3668 | B29: 36462 | G29: 5250528 | H29: 2377592
A30: 3279 | B30: 32540 | G30: 13341400 | H30: 2840750
A31: 2948 | B31: 9316 | G31: 1266976 | H31: 2704822
A32: 2749.6 | B32: 17172 | G32: 7830432 | H32: 3956927
B33: 16737 | G33: 6276375 | H33: 2726932
A34: 632 | B34: 35304 | G34: 10379376 | H34: 1590737
A35: 1932 | B35: 16841 | G35: 7713178 | H35: 4738764
A36: 1598.8 | B36: 18210.5 | G36: 7336230 | H36: 2229062
A37: 1933 | B37: 58687.2 | G37: 16296984 | H37: 1120895
B38: 7559.5 | G38: 1913135 | H38: 4680189
A39: 4452 | B39: 31745 | G39: 4412555 | H39: 4091720
A40: 2716 | B40: 12688 | G40: 2486848 | H40: 1413822
...

Sheet Data_Validation_Summary
A1: MUSIC FESTIVAL DATA VALIDATION REPORT
A3: 1. DATASET OVERVIEW
A4: Metric | B4: Value
A5: Total Records | B5: =COUNTA(Music_Festival_Data!A2:A106) -> 105
A6: Unique Festivals | B6: 10
A7: Unique Cities | B7: 10
A8: Unique Headlining Artists | B8: 11
A9: Date Range | B9: Jan 2024 - Dec 2024
A11: 2. DUPLICATE RECORDS ANALYSIS
A12: Duplicates Found | B12: =COUNTIF(Music_Festival_Data!N:N,"DUPLICATE - Remove") -> 5
A14: Row | B14: Festival | C14: City | D14: Date | E14: Artist | F14: Original Row
A15: 102 | B15: Goa Tribal Festival | C15: Goa | D15: 17-03-2024 | E15: Arijit Singh | F15: 70
A16: 103 | B16: Sunburn Goa | C16: Jaipur | D16: 13-05-2024 | E16: DJ Snake | F16: 94
A17: 104 | B17: NH7 Pune | C17: Chandigarh | D17: 45298 | E17: Martin Garrix | F17: 24
A18: 105 | B18: Lollapalooza Mumbai | C18: Kolkata | D18: 28-01-2024 | E18: Honey Singh | F18: 11
A19: 106 | B19: NH7 Pune | C19: Amritsar | D19: 13-12-2024 | E19: Honey Singh | F19: 30
A21: 3. MISSING VALUES ANALYSIS
A22: Column | B22: Missing Count | C22: Treatment Method | D22: Mean Value Used
A23: Tour_Name | B23: 63 | C23: Left blank (optional field) | D23: N/A
A24: Ticket_Price (Rs) | B24: 10 | C24: Filled with Mean | D24: ='Missing Values & Outliers'!E5 -> 2910.2168
A25: Total_Attendance | B25: 10 | C25: Filled with Mean | D25: ='Missing Values & Outliers'!E13 -> 20798.88
A29: 4. OUTLIER DETECTION (IQR Method)
A30: Total Outliers Flagged | B30: 8
A32: Outlier Thresholds (from Missing Values & Outliers sheet):
A33: Merchandise Sales - Upper Limit: | B33: ='Missing Values & Outliers'!K8 -> 15199758
A34: Sponsorship Revenue - Upper Limit: | B34: ='Missing Values & Outliers'!K15 -> 7312964
A37: 5. DATA QUALITY SUMMARY
A38: Issue | B38: Count | C38: Status | D38: Action Taken
A39: Duplicate Records | B39: 5 | C39: Removed | D39: Marked in Column N for removal
A40: Missing Ticket Prices | B40: 10 | C40: Resolved | D40: Imputed with mean (₹2,910.22)
A41: Missing Attendance | B41: 10 | C41: Resolved | D41: Imputed with mean (20,798.88)
A42: Outliers Detected | B42: 8 | C42: Removed | D42: Marked in Column J & L for review
A45: 6. CLEAN DATA STATISTICS
A46: Metric | B46: Value
A47: Valid Records (after removal of Duplicates and outliers) | B47: 93
A48: Total Revenue (Valid Records) | B48: =SUM('Cleaned Data'!M2:M93) -> 5964562939
A49: Total Attendance (Valid Records) | B49: =SUM('Cleaned Data'!I2:I93) -> 1802309.7
A50: Avg Ticket Price (Rs) | B50: =AVERAGE('Cleaned Data'!H2:H93) -> 2914.1931
A51: Total Merchandise Sales | B51: =SUM('Cleaned Data'!K2:K93) -> 520726263
A52: Total Sponsorship Revenue | B52: =SUM('Cleaned Data'!L2:L93) -> 268574250
...

Sheet Cleaned Data
A1: Festival_Name | B1: City | C1: Date | D1: Tour_Name | E1: Headlining_Artist | F1: International & Local Artists | G1: Supporting_Artists | H1: Ticket_Price(Rs) | I1: Total_Attendance | J1: Revenue per Event | K1: Merchandise_Sales (Rs) | L1: Sponsorship_Revenue (Rs) | M1: Total_Revenue (Rs) | N1: Artist_Name | O1: Genre | P1: Average_Ticket_Price | Q1: Average_Attendance_Per_City | R1: Social_Media_Followers (millions) | S1: Streaming_Plays (millions) | T1: Merchandise_Revenue_Per_Concert (Rs) | U1: Tour_Impact | V1: Cities_Performed_In
A2: NH7 Pune | B2: Kolkata | C2: 45303 | E2: Badshah | F2: =VLOOKUP(E2,'Missing Values & Outliers'!$O$10:$P$19,2,0) -> Local Artist | G2: DJ Snake, Honey Singh | H2: 1253 | I2: 6166 | J2: =I2*H2 -> 7725998 | K2: 1942290 | L2: 3680408 | M2: 13348696 | N2: {=VLOOKUP(E2,[1]Artist_Popularity_Data!$A$2:$I$11,{1,2,3,4,5,6,7,8,9},0)} -> Badshah | O2: Bollywood | P2: 3351 | Q2: 36448 | R2: 33 | S2: 483 | T2: 20228640 | U2: No | V2: Nagpur, Goa, Amritsar, Chandigarh, Mumbai
A3: NH7 Pune | B3: Bengaluru | C3: 45553 | D3: Classics Tour | E3: Bryan Adams | F3: =VLOOKUP(E3,'Missing Values & Outliers'!$O$10:$P$19,2,0) -> International | G3: Badshah, Arijit Singh, Martin Garrix, Diljit Dosanjh | H3: 6813.8 | I3: 17889.9 | J3: =I3*H3 -> 1.218982e+08 | K3: 7667100 | L3: 640053 | M3: 132693072 | N3: {=VLOOKUP(E3,[1]Artist_Popularity_Data!$A$2:$I$11,{1,2,3,4,5,6,7,8,9},0)} -> Bryan Adams | O3: Rock | P3: 992 | Q3: 21632.556 | R3: 30 | S3: 81 | T3: 8678356 | U3: Yes | V3: Delhi, Jaipur, Bengaluru, Mumbai
A4: VH1 Supersonic Delhi | B4: Goa | C4: 45353 | E4: Honey Singh | F4: =VLOOKUP(E4,'Missing Values & Outliers'!$O$10:$P$19,2,0) -> Local Artist | G4: Martin Garrix, Badshah, Ed Sheeran, Diljit Dosanjh | H4: 2144 | I4: 14688 | J4: =I4*H4 -> 31491072 | K4: 2350080 | L4: 2712686 | M4: 36553838 | N4: {=VLOOKUP(E4,[1]Artist_Popularity_Data!$A$2:$I$11,{1,2,3,4,5,6,7,8,9},0)} -> Honey Singh | O4: Hip-Hop | P4: 1573 | Q4: 35223 | R4: 34 | S4: 430 | T4: 25360560 | U4: No | V4: Pune, Amritsar, Bengaluru
A5: Hornbill Festival Nagaland | B5: Nagpur | C5: 45454 | D5: Soulful Nights Tour | E5: Arijit Singh | F5: =VLOOKUP(E5,'Missing Values & Outliers'!$O$10:$P$19,2,0) -> Local Artist | G5: Martin Garrix, Badshah | H5: 1886 | I5: 35244 | J5: =I5*H5 -> 66470184 | K5: 6132456 | L5: 1181193 | M5: 73783833 | N5: {=VLOOKUP(E5,[1]Artist_Popularity_Data!$A$2:$I$11,{1,2,3,4,5,6,7,8,9},0)} -> Arijit Singh | O5: Bollywood | P5: 2437 | Q5: 25729 | R5: 30 | S5: 584 | T5: 18730712 | U5: Yes | V5: Nagpur, Jaipur, Chandigarh
A6: Ziro Festival Arunachal | B6: Jaipur | C6: 45437 | E6: Mika Singh | F6: =VLOOKUP(E6,'Missing Values & Outliers'!$O$10:$P$19,2,0) -> Local Artist | G6: Diljit Dosanjh, Mika Singh | H6: 3984 | I6: 20798.88 | J6: =I6*H6 -> 82862738 | K6: 2252122 | L6: 2302603 | M6: 58605653 | N6: {=VLOOKUP(E6,[1]Artist_Popularity_Data!$A$2:$I$11,{1,2,3,4,5,6,7,8,9},0)} -> Mika Singh | O6: Bollywood | P6: 1025 | Q6: 11057 | R6: 12 | S6: 371 | T6: 7983154 | U6: No | V6: Delhi, Amritsar, Bengaluru, Mumbai
A7: Ziro Festival Arunachal | B7: Goa | C7: 45371 | D7: Classics Tour | E7: Bryan Adams | F7: =VLOOKUP(E7,'Missing Values & Outliers'!$O$10:$P$19,2,0) -> International | G7: Ed Sheeran, Mika Singh, Shreya Ghoshal, Bryan Adams | H7: 2910.2168 | I7: 18778.2 | J7: =I7*H7 -> 54648634 | K7: 4828680 | L7: 4948076 | M7: 111635078 | N7: {=VLOOKUP(E7,[1]Artist_Popularity_Data!$A$2:$I$11,{1,2,3,4,5,6,7,8,9},0)} -> Bryan Adams | O7: Rock | P7: 992 | Q7: 21632.556 | R7: 30 | S7: 81 | T7: 8678356 | U7: Yes | V7: Delhi, Jaipur, Bengaluru, Mumbai
A8: NH7 Pune | B8: Nagpur | C8: 45462 | E8: Badshah | F8: =VLOOKUP(E8,'Missing Values & Outliers'!$O$10:$P$19,2,0) -> Local Artist | G8: Honey Singh, Badshah, Bryan Adams, Martin Garrix | H8: 840 | I8: 33535 | J8: =I8*H8 -> 28169400 | K8: 12206740 | L8: 1201595 | M8: 41577735 | N8: {=VLOOKUP(E8,[1]Artist_Popularity_Data!$A$2:$I$11,{1,2,3,4,5,6,7,8,9},0)} -> Badshah | O8: Bollywood | P8: 3351 | Q8: 36448 | R8: 33 | S8: 483 | T8: 20228640 | U8: No | V8: Nagpur, Goa, Amritsar, Chandigarh, Mumbai
A9: Bollywood Music Project | B9: Delhi | C9: 45440 | E9: Shreya Ghoshal | F9: =VLOOKUP(E9,'Missing Values & Outliers'!$O$10:$P$19,2,0) -> Local Artist | G9: Ed Sheeran, Shreya Ghoshal, Bryan Adams, Badshah | H9: 4191 | I9: 20798.88 | J9: =I9*H9 -> 87168106 | K9: 4279770 | L9: 3427104 | M9: 81824709 | N9: {=VLOOKUP(E9,[1]Artist_Popularity_Data!$A$2:$I$11,{1,2,3,4,5,6,7,8,9},0)} -> Shreya Ghoshal | O9: Classical/Bollywood | P9: 3326 | Q9: 3197 | R9: 23 | S9: 271 | T9: 792856 | U9: No | V9: Pune, Mumbai, Delhi, Bengaluru, Amritsar
A10: Lollapalooza Mumbai | B10: Kolkata | C10: 45319 | E10: Honey Singh | F10: =VLOOKUP(E10,'Missing Values & Outliers'!$O$10:$P$19,2,0) -> Local Artist | G10: Honey Singh, Diljit Dosanjh | H10: 1823 | I10: 15513 | J10: =I10*H10 -> 28280199 | K10: 7539318 | L10: 3948781 | M10: 39768298 | N10: {=VLOOKUP(E10,[1]Artist_Popularity_Data!$A$2:$I$11,{1,2,3,4,5,6,7,8,9},0)} -> Honey Singh | O10: Hip-Hop | P10: 1573 | Q10: 35223 | R10: 34 | S10: 430 | T10: 25360560 | U10: No | V10: Pune, Amritsar, Bengaluru
A11: Hornbill Festival Nagaland | B11: Jaipur | C11: 45462 | E11: DJ Snake | F11: =VLOOKUP(E11,'Missing Values & Outliers'!$O$10:$P$19,2,0) -> International | G11: Honey Singh, Diljit Dosanjh, Arijit Singh | H11: 3953.6 | I11: 21693 | J11: =I11*H11 -> 85765445 | K11: 9306297 | L11: 4798020 | M11: 75365349 | N11: {=VLOOKUP(E11,[1]Artist_Popularity_Data!$A$2:$I$11,{1,2,3,4,5,6,7,8,9},0)} -> DJ Snake | O11: EDM | P11: 1431 | Q11: 19089 | R11: 32 | S11: 429 | T11: 10193526 | U11: No | V11: Bengaluru, Jaipur, Mumbai, Chandigarh, Kolkata, Delhi
A12: Sunburn Goa | B12: Goa | C12: 45649 | E12: Shreya Ghoshal | F12: =VLOOKUP(E12,'Missing Values & Outliers'!$O$10:$P$19,2,0) -> Local Artist | G12: Honey Singh, Badshah, Bryan Adams | H12: 2842 | I12: 24021 | J12: =I12*H12 -> 68267682 | K12: 5020389 | L12: 2851905 | M12: 76139976 | N12: {=VLOOKUP(E12,[1]Artist_Popularity_Data!$A$2:$I$11,{1,2,3,4,5,6,7,8,9},0)} -> Shreya Ghoshal | O12: Classical/Bollywood | P12: 3326 | Q12: 3197 | R12: 23 | S12: 271 | T12: 792856 | U12: No | V12: Pune, Mumbai, Delhi, Bengaluru, Amritsar
A13: Supersonic Bengaluru | B13: Pune | C13: 45428 | D13: Born To Shine Tour | E13: Diljit Dosanjh | F13: =VLOOKUP(E13,'Missing Values & Outliers'!$O$10:$P$19,2,0) -> Local Artist | G13: Mika Singh, Ed Sheeran, Arijit Singh | H13: 528 | I13: 33241 | J13: =I13*H13 -> 17551248 | K13: 2659280 | L13: 3167786 | M13: 19328026 | N13: {=VLOOKUP(E13,[1]Artist_Popularity_Data!$A$2:$I$11,{1,2,3,4,5,6,7,8,9},0)} -> Diljit Dosanjh | O13: Punjabi | P13: 2027 | Q13: 33738 | R13: 46 | S13: 116 | T13: 22334556 | U13: Yes | V13: Amritsar, Kolkata, Delhi, Mumbai, Bengaluru
A14: Magnetic Fields Rajasthan | B14: Mumbai | C14: 45644 | E14: Martin Garrix | F14: =VLOOKUP(E14,'Missing Values & Outliers'!$O$10:$P$19,2,0) -> International | G14: Shreya Ghoshal, Ed Sheeran, Arijit Singh | H14: 1543 | I14: 19867 | J14: =I14*H14 -> 30654781 | K14: 2821114 | L14: 2897760 | M14: 36373655 | N14: {=VLOOKUP(E14,[1]Artist_Popularity_Data!$A$2:$I$11,{1,2,3,4,5,6,7,8,9},0)} -> Martin Garrix | O14: EDM | P14: 2499 | Q14: 11603 | R14: 43 | S14: 298 | T14: 6462871 | U14: No | V14: Chandigarh, Delhi, Pune, Nagpur, Bengaluru, Kolkata
A15: Hornbill Festival Nagaland | B15: Amritsar | C15: 45344 | E15: Shreya Ghoshal | F15: =VLOOKUP(E15,'Missing Values & Outliers'!$O$10:$P$19,2,0) -> Local Artist | G15: Bryan Adams, Badshah, Honey Singh | H15: 2188 | I15: 20603 | J15: =I15*H15 -> 45079364 | K15: 9559792 | L15: 4600450 | M15: 59239606 | N15: {=VLOOKUP(E15,[1]Artist_Popularity_Data!$A$2:$I$11,{1,2,3,4,5,6,7,8,9},0)} -> Shreya Ghoshal | O15: Classical/Bollywood | P15: 3326 | Q15: 3197 | R15: 23 | S15: 271 | T15: 792856 | U15: No | V15: Pune, Mumbai, Delhi, Bengaluru, Amritsar
A16: VH1 Supersonic Delhi | B16: Kolkata | C16: 45581 | D16: Classics Tour | E16: Bryan Adams | F16: =VLOOKUP(E16,'Missing Values & Outliers'!$O$10:$P$19,2,0) -> International | G16: Ed Sheeran, Shreya Ghoshal | H16: 2217.6 | I16: 9504.6 | J16: =I16*H16 -> 21077401 | K16: 5892852 | L16: 795307 | M16: 28195711 | N16: {=VLOOKUP(E16,[1]Artist_Popularity_Data!$A$2:$I$11,{1,2,3,4,5,6,7,8,9},0)} -> Bryan Adams | O16: Rock | P16: 992 | Q16: 21632.556 | R16: 30 | S16: 81 | T16: 8678356 | U16: Yes | V16: Delhi, Jaipur, Bengaluru, Mumbai
A17: Lollapalooza Mumbai | B17: Delhi | C17: 45455 | D17: Classics Tour | E17: Bryan Adams | F17: =VLOOKUP(E17,'Missing Values & Outliers'!$O$10:$P$19,2,0) -> International | G17: Martin Garrix, Mika Singh, Bryan Adams | H17: 5397 | I17: 9158.1 | J17: =I17*H17 -> 49426266 | K17: 1687707 | L17: 2188470 | M17: 54311142 | N17: {=VLOOKUP(E17,[1]Artist_Popularity_Data!$A$2:$I$11,{1,2,3,4,5,6,7,8,9},0)} -> Bryan Adams | O17: Rock | P17: 992 | Q17: 21632.556 | R17: 30 | S17: 81 | T17: 8678356 | U17: Yes | V17: Delhi, Jaipur, Bengaluru, Mumbai
A18: Ziro Festival Arunachal | B18: Pune | C18: 45384 | D18: Mathematics Tour | E18: Ed Sheeran | F18: =VLOOKUP(E18,'Missing Values & Outliers'!$O$10:$P$19,2,0) -> International | G18: Honey Singh, Ed Sheeran | H18: 1601.6 | I18: 11790 | J18: =I18*H18 -> 18882864 | K18: 3030030 | L18: 3635278 | M18: 20153068 | N18: {=VLOOKUP(E18,[1]Artist_Popularity_Data!$A$2:$I$11,{1,2,3,4,5,6,7,8,9},0)} -> Ed Sheeran | O18: International Pop | P18: 3436 | Q18: 18609 | R18: 55 | S18: 736 | T18: 4856949 | U18: Yes | V18: Pune, Amritsar, Goa, Chandigarh
A19: Ziro Festival Arunachal | B19: Delhi | C19: 45531 | E19: Shreya Ghoshal | F19: =VLOOKUP(E19,'Missing Values & Outliers'!$O$10:$P$19,2,0) -> Local Artist | G19: Honey Singh, Mika Singh, Martin Garrix, Ed Sheeran | H19: 4564 | I19: 31755 | J19: =I19*H19 -> 144929820 | K19: 6890835 | L19: 4732974 | M19: 156553629 | N19: {=VLOOKUP(E19,[1]Artist_Popularity_Data!$A$2:$I$11,{1,2,3,4,5,6,7,8,9},0)} -> Shreya Ghoshal | O19: Classical/Bollywood | P19: 3326 | Q19: 3197 | R19: 23 | S19: 271 | T19: 792856 | U19: No | V19: Pune, Mumbai, Delhi, Bengaluru, Amritsar
A20: Sunburn Goa | B20: Nagpur | C20: 45634 | D20: Classics Tour | E20: Bryan Adams | F20: =VLOOKUP(E20,'Missing Values & Outliers'!$O$10:$P$19,2,0) -> International | G20: Ed Sheeran, Mika Singh, Shreya Ghoshal, Honey Singh | H20: 3350.2 | I20: 2975.7 | J20: =I20*H20 -> 9969190.1 | K20: 1041495 | L20: 3001940 | M20: 14216078 | N20: {=VLOOKUP(E20,[1]Artist_Popularity_Data!$A$2:$I$11,{1,2,3,4,5,6,7,8,9},0)} -> Bryan Adams | O20: Rock | P20: 992 | Q20: 21632.556 | R20: 30 | S20: 81 | T20: 8678356 | U20: Yes | V20: Delhi, Jaipur, Bengaluru, Mumbai
A21: Sunburn Goa | B21: Delhi | C21: 45460 | E21: Badshah | F21: =VLOOKUP(E21,'Missing Values & Outliers'!$O$10:$P$19,2,0) -> Local Artist | G21: Shreya Ghoshal, Diljit Dosanjh, Arijit Singh | H21: 4045 | I21: 27719 | J21: =I21*H21 -> 112123355 | K21: 7539568 | L21: 4670910 | M21: 124333833 | N21: {=VLOOKUP(E21,[1]Artist_Popularity_Data!$A$2:$I$11,{1,2,3,4,5,6,7,8,9},0)} -> Badshah | O21: Bollywood | P21: 3351 | Q21: 36448 | R21: 33 | S21: 483 | T21: 20228640 | U21: No | V21: Nagpur, Goa, Amritsar, Chandigarh, Mumbai
A22: Sunburn Goa | B22: Bengaluru | C22: 45425 | D22: Soulful Nights Tour | E22: Arijit Singh | F22: =VLOOKUP(E22,'Missing Values & Outliers'!$O$10:$P$19,2,0) -> Local Artist | G22: Honey Singh, Diljit Dosanjh, Badshah | H22: 1008 | I22: 21142 | J22: =I22*H22 -> 21311136 | K22: 2558182 | L22: 1632574 | M22: 25501892 | N22: {=VLOOKUP(E22,[1]Artist_Popularity_Data!$A$2:$I$11,{1,2,3,4,5,6,7,8,9},0)} -> Arijit Singh | O22: Bollywood | P22: 2437 | Q22: 25729 | R22: 30 | S22: 584 | T22: 18730712 | U22: Yes | V22: Nagpur, Jaipur, Chandigarh
A23: NH7 Pune | B23: Chandigarh | C23: 45474 | E23: Martin Garrix | F23: =VLOOKUP(E23,'Missing Values & Outliers'!$O$10:$P$19,2,0) -> International | G23: Honey Singh, Bryan Adams, DJ Snake | H23: 2334 | I23: 16842 | J23: =I23*H23 -> 39309228 | K23: 6905220 | L23: 1067015 | M23: 47281463 | N23: {=VLOOKUP(E23,[1]Artist_Popularity_Data!$A$2:$I$11,{1,2,3,4,5,6,7,8,9},0)} -> Martin Garrix | O23: EDM | P23: 2499 | Q23: 11603 | R23: 43 | S23: 298 | T23: 6462871 | U23: No | V23: Chandigarh, Delhi, Pune, Nagpur, Bengaluru, Kolkata
A24: Goa Tribal Festival | B24: Delhi | C24: 45299 | D24: Born To Shine Tour | E24: Diljit Dosanjh | F24: =VLOOKUP(E24,'Missing Values & Outliers'!$O$10:$P$19,2,0) -> Local Artist | G24: Ed Sheeran, Diljit Dosanjh, Shreya Ghoshal, Badshah | H24: 2910.2168 | I24: 14456 | J24: =I24*H24 -> 42070095 | K24: 4603680 | L24: 2403962 | M24: 41090442 | N24: {=VLOOKUP(E24,[1]Artist_Popularity_Data!$A$2:$I$11,{1,2,3,4,5,6,7,8,9},0)} -> Diljit Dosanjh | O24: Punjabi | P24: 2027 | Q24: 33738 | R24: 46 | S24: 116 | T24: 22334556 | U24: Yes | V24: Amritsar, Kolkata, Delhi, Mumbai, Bengaluru
A25: Magnetic Fields Rajasthan | B25: Amritsar | C25: 45416 | E25: Badshah | F25: =VLOOKUP(E25,'Missing Values & Outliers'!$O$10:$P$19,2,0) -> Local Artist | G25: Mika Singh, Diljit Dosanjh, Martin Garrix | H25: 3977 | I25: 25243 | J25: =I25*H25 -> 100391411 | K25: 9238938 | L25: 4689343 | M25: 114319692 | N25: {=VLOOKUP(E25,[1]Artist_Popularity_Data!$A$2:$I$11,{1,2,3,4,5,6,7,8,9},0)} -> Badshah | O25: Bollywood | P25: 3351 | Q25: 36448 | R25: 33 | S25: 483 | T25: 20228640 | U25: No | V25: Nagpur, Goa, Amritsar, Chandigarh, Mumbai
A26: Sunburn Goa | B26: Jaipur | C26: 45407 | E26: Honey Singh | F26: =VLOOKUP(E26,'Missing Values & Outliers'!$O$10:$P$19,2,0) -> Local Artist | G26: Bryan Adams, Diljit Dosanjh, Honey Singh, Mika Singh | H26: 3449 | I26: 13539 | J26: =I26*H26 -> 46696011 | K26: 5672841 | L26: 3471436 | M26: 55840288 | N26: {=VLOOKUP(E26,[1]Artist_Popularity_Data!$A$2:$I$11,{1,2,3,4,5,6,7,8,9},0)} -> Honey Singh | O26: Hip-Hop | P26: 1573 | Q26: 35223 | R26: 34 | S26: 430 | T26: 25360560 | U26: No | V26: Pune, Amritsar, Bengaluru
A27: Hornbill Festival Nagaland | B27: Pune | C27: 45316 | E27: Badshah | F27: =VLOOKUP(E27,'Missing Values & Outliers'!$O$10:$P$19,2,0) -> Local Artist | G27: Martin Garrix, Bryan Adams, DJ Snake | H27: 3668 | I27: 36462 | J27: =I27*H27 -> 133742616 | K27: 5250528 | L27: 2377592 | M27: 141370736 | N27: {=VLOOKUP(E27,[1]Artist_Popularity_Data!$A$2:$I$11,{1,2,3,4,5,6,7,8,9},0)} -> Badshah | O27: Bollywood | P27: 3351 | Q27: 36448 | R27: 33 | S27: 483 | T27: 20228640 | U27: No | V27: Nagpur, Goa, Amritsar, Chandigarh, Mumbai
A28: NH7 Pune | B28: Goa | C28: 45539 | E28: Badshah | F28: =VLOOKUP(E28,'Missing Values & Outliers'!$O$10:$P$19,2,0) -> Local Artist | G28: Arijit Singh, Diljit Dosanjh | H28: 3279 | I28: 32540 | J28: =I28*H28 -> 106698660 | K28: 13341400 | L28: 2840750 | M28: 122880810 | N28: {=VLOOKUP(E28,[1]Artist_Popularity_Data!$A$2:$I$11,{1,2,3,4,5,6,7,8,9},0)} -> Badshah | O28: Bollywood | P28: 3351 | Q28: 36448 | R28: 33 | S28: 483 | T28: 20228640 | U28: No | V28: Nagpur, Goa, Amritsar, Chandigarh, Mumbai
A29: NH7 Pune | B29: Amritsar | C29: 45639 | E29: Honey Singh | F29: =VLOOKUP(E29,'Missing Values & Outliers'!$O$10:$P$19,2,0) -> Local Artist | G29: Diljit Dosanjh, Honey Singh, DJ Snake, Shreya Ghoshal | H29: 2948 | I29: 9316 | J29: =I29*H29 -> 27463568 | K29: 1266976 | L29: 2704822 | M29: 31435366 | N29: {=VLOOKUP(E29,[1]Artist_Popularity_Data!$A$2:$I$11,{1,2,3,4,5,6,7,8,9},0)} -> Honey Singh | O29: Hip-Hop | P29: 1573 | Q29: 35223 | R29: 34 | S29: 430 | T29: 25360560 | U29: No | V29: Pune, Amritsar, Bengaluru
A30: NH7 Pune | B30: Delhi | C30: 45647 | E30: DJ Snake | F30: =VLOOKUP(E30,'Missing Values & Outliers'!$O$10:$P$19,2,0) -> International | G30: Bryan Adams, Mika Singh, Arijit Singh | H30: 2749.6 | I30: 17172 | J30: =I30*H30 -> 47216131 | K30: 7830432 | L30: 3956927 | M30: 45513167 | N30: {=VLOOKUP(E30,[1]Artist_Popularity_Data!$A$2:$I$11,{1,2,3,4,5,6,7,8,9},0)} -> DJ Snake | O30: EDM | P30: 1431 | Q30: 19089 | R30: 32 | S30: 429 | T30: 10193526 | U30: No | V30: Bengaluru, Jaipur, Mumbai, Chandigarh, Kolkata, Delhi
A31: Ziro Festival Arunachal | B31: Bengaluru | C31: 45410 | E31: Honey Singh | F31: =VLOOKUP(E31,'Missing Values & Outliers'!$O$10:$P$19,2,0) -> Local Artist | G31: Arijit Singh, Honey Singh | H31: 2910.2168 | I31: 16737 | J31: =I31*H31 -> 48708299 | K31: 6276375 | L31: 2726932 | M31: 85424449 | N31: {=VLOOKUP(E31,[1]Artist_Popularity_Data!$A$2:$I$11,{1,2,3,4,5,6,7,8,9},0)} -> Honey Singh | O31: Hip-Hop | P31: 1573 | Q31: 35223 | R31: 34 | S31: 430 | T31: 25360560 | U31: No | V31: Pune, Amritsar, Bengaluru
A32: NH7 Pune | B32: Chandigarh | C32: 45392 | E32: Shreya Ghoshal | F32: =VLOOKUP(E32,'Missing Values & Outliers'!$O$10:$P$19,2,0) -> Local Artist | G32: Martin Garrix, Diljit Dosanjh, Badshah, Mika Singh | H32: 632 | I32: 35304 | J32: =I32*H32 -> 22312128 | K32: 10379376 | L32: 1590737 | M32: 34282241 | N32: {=VLOOKUP(E32,[1]Artist_Popularity_Data!$A$2:$I$11,{1,2,3,4,5,6,7,8,9},0)} -> Shreya Ghoshal | O32: Classical/Bollywood | P32: 3326 | Q32: 3197 | R32: 23 | S32: 271 | T32: 792856 | U32: No | V32: Pune, Mumbai, Delhi, Bengaluru, Amritsar
A33: Goa Tribal Festival | B33: Kolkata | C33: 45360 | E33: Honey Singh | F33: =VLOOKUP(E33,'Missing Values & Outliers'!$O$10:$P$19,2,0) -> Local Artist | G33: DJ Snake, Arijit Singh, Badshah, Mika Singh | H33: 1932 | I33: 16841 | J33: =I33*H33 -> 32536812 | K33: 7713178 | L33: 4738764 | M33: 44988754 | N33: {=VLOOKUP(E33,[1]Artist_Popularity_Data!$A$2:$I$11,{1,2,3,4,5,6,7,8,9},0)} -> Honey Singh | O33: Hip-Hop | P33: 1573 | Q33: 35223 | R33: 34 | S33: 430 | T33: 25360560 | U33: No | V33: Pune, Amritsar, Bengaluru
A34: Ziro Festival Arunachal | B34: Goa | C34: 45358 | D34: Classics Tour | E34: Bryan Adams | F34: =VLOOKUP(E34,'Missing Values & Outliers'!$O$10:$P$19,2,0) -> International | G34: Mika Singh, Diljit Dosanjh, Shreya Ghoshal | H34: 1598.8 | I34: 18210.5 | J34: =I34*H34 -> 29114947 | K34: 7336230 | L34: 2229062 | M34: 39274422 | N34: {=VLOOKUP(E34,[1]Artist_Popularity_Data!$A$2:$I$11,{1,2,3,4,5,6,7,8,9},0)} -> Bryan Adams | O34: Rock | P34: 992 | Q34: 21632.556 | R34: 30 | S34: 81 | T34: 8678356 | U34: Yes | V34: Delhi, Jaipur, Bengaluru, Mumbai
A35: Lollapalooza Mumbai | B35: Bengaluru | C35: 45395 | D35: Born To Shine Tour | E35: Diljit Dosanjh | F35: =VLOOKUP(E35,'Missing Values & Outliers'!$O$10:$P$19,2,0) -> Local Artist | G35: Diljit Dosanjh, DJ Snake, Honey Singh, Shreya Ghoshal | H35: 2910.2168 | I35: 7559.5 | J35: =I35*H35 -> 21999784 | K35: 1913135 | L35: 4680189 | M35: 21654174 | N35: {=VLOOKUP(E35,[1]Artist_Popularity_Data!$A$2:$I$11,{1,2,3,4,5,6,7,8,9},0)} -> Diljit Dosanjh | O35: Punjabi | P35: 2027 | Q35: 33738 | R35: 46 | S35: 116 | T35: 22334556 | U35: Yes | V35: Amritsar, Kolkata, Delhi, Mumbai, Bengaluru
A36: VH1 Supersonic Delhi | B36: Bengaluru | C36: 45509 | E36: Martin Garrix | F36: =VLOOKUP(E36,'Missing Values & Outliers'!$O$10:$P$19,2,0) -> International | G36: DJ Snake, Honey Singh, Diljit Dosanjh | H36: 4452 | I36: 31745 | J36: =I36*H36 -> 141328740 | K36: 4412555 | L36: 4091720 | M36: 149833015 | N36: {=VLOOKUP(E36,[1]Artist_Popularity_Data!$A$2:$I$11,{1,2,3,4,5,6,7,8,9},0)} -> Martin Garrix | O36: EDM | P36: 2499 | Q36: 11603 | R36: 43 | S36: 298 | T36: 6462871 | U36: No | V36: Chandigarh, Delhi, Pune, Nagpur, Bengaluru, Kolkata
A37: Bollywood Music Project | B37: Mumbai | C37: 45555 | E37: Mika Singh | F37: =VLOOKUP(E37,'Missing Values & Outliers'!$O$10:$P$19,2,0) -> Local Artist | G37: Arijit Singh, DJ Snake, Martin Garrix | H37: 2716 | I37: 12688 | J37: =I37*H37 -> 34460608 | K37: 2486848 | L37: 1413822 | M37: 38361278 | N37: {=VLOOKUP(E37,[1]Artist_Popularity_Data!$A$2:$I$11,{1,2,3,4,5,6,7,8,9},0)} -> Mika Singh | O37: Bollywood | P37: 1025 | Q37: 11057 | R37: 12 | S37: 371 | T37: 7983154 | U37: No | V37: Delhi, Amritsar, Bengaluru, Mumbai
A38: Sunburn Goa | B38: Chandigarh | C38: 45507 | E38: Mika Singh | F38: =VLOOKUP(E38,'Missing Values & Outliers'!$O$10:$P$19,2,0) -> Local Artist | G38: DJ Snake, Badshah | H38: 2237 | I38: 20276 | J38: =I38*H38 -> 45357412 | K38: 9671652 | L38: 4912334 | M38: 59941398 | N38: {=VLOOKUP(E38,[1]Artist_Popularity_Data!$A$2:$I$11,{1,2,3,4,5,6,7,8,9},0)} -> Mika Singh | O38: Bollywood | P38: 1025 | Q38: 11057 | R38: 12 | S38: 371 | T38: 7983154 | U38: No | V38: Delhi, Amritsar, Bengaluru, Mumbai
A39: Bollywood Music Project | B39: Nagpur | C39: 45468 | E39: Badshah | F39: =VLOOKUP(E39,'Missing Values & Outliers'!$O$10:$P$19,2,0) -> Local Artist | G39: DJ Snake, Honey Singh, Diljit Dosanjh | H39: 1412 | I39: 20798.88 | J39: =I39*H39 -> 29368019 | K39: 12753000 | L39: 663225 | M39: 61435521 | N39: {=VLOOKUP(E39,[1]Artist_Popularity_Data!$A$2:$I$11,{1,2,3,4,5,6,7,8,9},0)} -> Badshah | O39: Bollywood | P39: 3351 | Q39: 36448 | R39: 33 | S39: 483 | T39: 20228640 | U39: No | V39: Nagpur, Goa, Amritsar, Chandigarh, Mumbai
A40: Bollywood Music Project | B40: Goa | C40: 45654 | D40: Born To Shine Tour | E40: Diljit Dosanjh | F40: =VLOOKUP(E40,'Missing Values & Outliers'!$O$10:$P$19,2,0) -> Local Artist | G40: Diljit Dosanjh, Shreya Ghoshal, Ed Sheeran | H40: 836 | I40: 56160 | J40: =I40*H40 -> 46949760 | K40: 14904000 | L40: 4753926 | M40: 55773126 | N40: {=VLOOKUP(E40,[1]Artist_Popularity_Data!$A$2:$I$11,{1,2,3,4,5,6,7,8,9},0)} -> Diljit Dosanjh | O40: Punjabi | P40: 2027 | Q40: 33738 | R40: 46 | S40: 116 | T40: 22334556 | U40: Yes | V40: Amritsar, Kolkata, Delhi, Mumbai, Bengaluru
...

Sheet Stage2
A1: Peak Season for Festivals in India
A3: Row Labels | B3: Sum of Total_Revenue (Rs) | C3: Sum of Total_Revenue (Rs)2
A4: Jan | B4: 471168417 | C4: 0.078994626
A5: Feb | B5: 328171218 | C5: 0.055020162
A6: Mar | B6: 406005910 | C6: 0.068069683
A7: Apr | B7: 380768959 | C7: 0.063838535
A8: May | B8: 591637363 | C8: 0.099192073
A9: Jun | B9: 536416537 | C9: 0.089933922
A10: Jul | B10: 493875206 | C10: 0.082801575
A11: Aug | B11: 848183953 | C11: 0.14220387
A12: Sep | B12: 695359429 | C12: 0.11658179
A13: Oct | B13: 91024006 | C13: 0.015260801
A14: Nov | B14: 256909552 | C14: 0.043072653
A15: Dec | B15: 865042389 | C15: 0.14503031
A16: Grand Total | B16: 5964562939 | C16: 1
A21: August and Decemeber shows the best season for Music Festivals in India.
A26: Row Labels | B26: Total_Revenue1 (Rs) | C26: Total_Attendance1
A27: Jan | B27: 471168417 | C27: 147506.5
A28: Feb | B28: 328171218 | C28: 95928.1
A29: Mar | B29: 406005910 | C29: 99290.7
A30: Apr | B30: 380768959 | C30: 145057.6
A31: May | B31: 591637363 | C31: 196145.76
A32: Jun | B32: 536416537 | C32: 208472.74
A33: Jul | B33: 493875206 | C33: 121054
A34: Aug | B34: 848183953 | C34: 256917.18
A35: Sep | B35: 695359429 | C35: 142573
A36: Oct | B36: 91024006 | C36: 29962.6
A37: Nov | B37: 256909552 | C37: 98336.96
A38: Dec | B38: 865042389 | C38: 261064.58
A39: Grand Total | B39: 5964562939 | C39: 1802309.7
A43: We can see that, seasonal trends impact attendance, making it crucial to align festival dates with periods of high demand.
A44: December is the best season for Music Festivals in India with 14.49% attendance being the highest for whole year
A49: Row Labels | B49: Total Revenue(Rs) | C49: Total Attendance
A50: Pune | B50: 479288314 | C50: 150798.48
A51: Nagpur | B51: 831769738 | C51: 227873.96
A52: Mumbai | B52: 171830232 | C52: 79127.2
A53: Kolkata | B53: 594009538 | C53: 144910.2
A54: Jaipur | B54: 752723987 | C54: 234934.98
A55: Goa | B55: 1073141556 | C55: 369065.58
A56: Delhi | B56: 744828479 | C56: 173785.96
...

Sheet Stage3
A1: Optimizing Ticket Pricing for Maximum Revenue
A3: Row Labels | B3: Average of Ticket_Price(Rs) | C3: Total Attendance
A4: Chandigarh | B4: 2033.9 | C4: 0.086131755
A5: Mumbai | B5: 2489.6 | C5: 0.04390322
A6: Goa | B6: 2564.8822 | C6: 0.20477367
A7: Nagpur | B7: 2637.2333 | C7: 0.12643441
A8: Amritsar | B8: 2686.6667 | C8: 0.064240268
A9: Kolkata | B9: 2832.2 | C9: 0.080402496
A10: Pune | B10: 2880.0595 | C10: 0.08366957
A11: Jaipur | B11: 3035.894 | C11: 0.13035217
A12: Bengaluru | B12: 3704.1434 | C12: 0.083668416
A13: Delhi | B13: 3989.2251 | C13: 0.096424026
A14: Grand Total | B14: 2914.1931 | C14: 1
A20: This chart clearly shows that if the price of the ticket increases, attendance decreases.
A21: Delhi & Bengluru has the highest ticket price with very low attendance whereas Goa has the highest attendance and medium ticket price
A24: Row Labels | B24: Count of Festival_Name | C24: Average of Total_Revenue (Rs) | D24: Total_Revenue (Rs)2 | E24: Total_Attendance2 | F24: Average of Total_Attendance | G24: Attedance%
A25: 500-1500 | B25: 16 | C25: 31956668 | D25: 511306692 | E25: 425026.36 | F25: 26564.147 | G25: 0.23582315
A26: 1500-2500 | B26: 17 | C26: 58795105 | D26: 999516783 | E26: 311548.98 | F26: 18326.411 | G26: 0.17286096
A27: 2500-3500 | B27: 30 | C27: 53525398 | D27: 1605761941 | E27: 458178.04 | F27: 15272.601 | G27: 0.25421715
A28: 3500-4500 | B28: 17 | C28: 99554239 | D28: 1692422060 | E28: 426047.44 | F28: 25061.614 | G28: 0.23638969
A29: 4500-5500 | B29: 10 | C29: 85223082 | D29: 852230819 | E29: 141937.9 | F29: 14193.79 | G29: 0.078753334
A30: 6500-7500 | B30: 2 | C30: 151662322 | D30: 303324644 | E30: 39571 | F30: 19785.5 | G30: 0.021955716
A31: Grand Total | B31: 92 | C31: 64832206 | D31: 5964562939 | E31: 1802309.7 | F31: 19590.323 | G31: 1
A34: Attendance Analysis:
A35: ₹2,500 - ₹3,500 range has HIGHEST ATTENDANCE (25.42% of total) with 458,178 attendees across 30 festivals
A36: ₹500 - ₹1,500 range has HIGHEST AVG ATTENDANCE per festival (26,564) - budget-friendly attracts crowds
A39: Profitability Analysis:
A40: ₹3,500 - ₹4,500 range: HIGHEST Avg Revenue per Festival- best profitability per event
A41: ₹2,500 - ₹3,500 range: HIGHEST Total Revenue (₹160.6 Cr) - volume drives overall revenue
A44: Avoid tickets above 5500 as it drastically affects the attendance
A46: Correlation of Ticket price & Total Attendance | C46: =CORREL('Cleaned Data'!H2:H93,'Cleaned Data'!I2:I93) -> -0.18753532
A48: This Correlation shows that if the value of ticket increases the attendance count goes down.
A49: Not drastically but it do affect at some point.

Sheet Stage4
A1: Impact of International vs. Local Artists on Ticket Sales
A4: Row Labels | B4: Total Revenue | C4: Total Attendance | D4: Event Count | E4: Avg Attendance/Event | F4: Avg Revenue / Event
A5: Arijit Singh | B5: 488510395 | C5: 186321.88 | D5: 12 | E5: =C5/D5 -> 15526.823 | F5: =B5/D5 -> 40709200
A6: Badshah | B6: 1012375595 | C6: 259551.88 | D6: 12 | E6: =C6/D6 -> 21629.323 | F6: =B6/D6 -> 84364633
A7: Bryan Adams | B7: 832634949 | C7: 182197.18 | D7: 12 | E7: =C7/D7 -> 15183.098 | F7: =B7/D7 -> 69386246
A8: Diljit Dosanjh | B8: 453627757 | C8: 252102.5 | D8: 8 | E8: =C8/D8 -> 31512.813 | F8: =B8/D8 -> 56703470
A9: DJ Snake | B9: 487828759 | C9: 127284.88 | D9: 7 | E9: =C9/D9 -> 18183.554 | F9: =B9/D9 -> 69689823
A10: Ed Sheeran | B10: 109382356 | C10: 52871.88 | D10: 4 | E10: =C10/D10 -> 13217.97 | F10: =B10/D10 -> 27345589
A11: Honey Singh | B11: 877653513 | C11: 174435 | D11: 11 | E11: =C11/D11 -> 15857.727 | F11: =B11/D11 -> 79786683
A12: Martin Garrix | B12: 336379539 | C12: 116336 | D12: 6 | E12: =C12/D12 -> 19389.333 | F12: =B12/D12 -> 56063256
A13: Mika Singh | B13: 658312538 | C13: 232532.88 | D13: 10 | E13: =C13/D13 -> 23253.288 | F13: =B13/D13 -> 65831254
A14: Shreya Ghoshal | B14: 707857538 | C14: 218675.64 | D14: 10 | E14: =C14/D14 -> 21867.564 | F14: =B14/D14 -> 70785754
A15: Grand Total | B15: 5964562939 | C15: 1802309.7 | D15: 92 | E15: =C15/D15 -> 19590.323 | F15: =B15/D15 -> 64832206
A19: KEY POINTS:
A20: • Badshah draws the MOST total attendees(2,59,552) - best for maximizing turnout
A21: • Badshah generates HIGHEST revenue(1,01,23,75,595) - best for revenue optimization
A22: • Diljit Dosanjh has HIGHEST per-event attendance (31,513 avg) - most consistent crowd puller
A25: STRATEGIC RECOMMENDATIONS:
A26: • For MAX TURNOUT: Book Badshah, Diljit Dosanjh, or Mika Singh as headliners
A27: • For MAX REVENUE: Prioritize Badshah, Honey Singh or Bryan Adams
A28: • For BALANCED PERFORMANCE: Honey Singh, Shreya Ghoshal offer good attendance + revenue mix
A30: INSIGHT | B30: ARTIST | C30: VALUE(Rs) | D30: IMPLICATION
A31: Top Attendance Driver | B31: Badshah | C31: 259551.88 | D31: Best for maximizing crowd size
A32: Top Revenue Driver | B32: Badshah | C32: 1012375595 | D32: Best for maximizing festival income
A33: Best Per-Event Avg Attendance | B33: Diljit Dosanjh | C33: 31512.813 | D33: Most consistent crowd pull per show
A38: Row Labels | B38: Total Revenue | C38: Total Attendance | D38: Average of Total_Attendance
A39: Bollywood | B39: 2159198528 | C39: 678406.64 | D39: 19953.136
A40: Classical/Bollywood | B40: 707857538 | C40: 218675.64 | D40: 21867.564
A41: EDM | B41: 824208298 | C41: 243620.88 | D41: 18740.068
A42: Hip-Hop | B42: 877653513 | C42: 174435 | D42: 15857.727
A43: International Pop | B43: 109382356 | C43: 52871.88 | D43: 13217.97
A44: Punjabi | B44: 453627757 | C44: 252102.5 | D44: 31512.813
A45: Rock | B45: 832634949 | C45: 182197.18 | D45: 15183.098
A46: Grand Total | B46: 5964562939 | C46: 1802309.7 | D46: 19590.323
A49: KEY POINTS:
A50: Genre-Bollywood is the music style which attracts the largest crowd
A51: Punjabi has the highest Avg Attendance which means Festival-goers generally prefer this genre.
A54: Row Labels | B54: Total Events | C54: Total Attendance3 | D54: Total Revenue3 | E54: Average of Ticket_Price(Rs) | F54: Revenue/Attendance
A55: International | B55: 29 | C55: 478689.94 | D55: 1766225603 | E55: 3223.4075 | F55: =D55/C55 -> 3689.707
A56: Local Artist | B56: 63 | C56: 1323619.8 | D56: 4198337336 | E56: 2771.8564 | F56: =D56/C56 -> 3171.8605
...

Sheet Stage5
A1: The Role of Sponsorship and Merchandise in Festival Profitability
B4: Row Labels | C4: Total Sponsorship Revenue(Rs) | D4: Total Merchandise Revenue(Rs) | E4: Total Revenue(Rs) | F4: Sponsorship_Revenue % | G4: Merchandise_Revenue % | H4: Spon+Merch
B5: Bollywood Music Project | C5: 24890409 | D5: 70150425 | E5: 808366341 | F5: =$C5/$E5 -> 0.030791001 | G5: =$D5/$E5 -> 0.086780487 | H5: =G5+F5 -> 0.11757149
B6: Goa Tribal Festival | C6: 13640304 | D6: 34422086 | E6: 262562788 | F6: =$C6/$E6 -> 0.051950637 | G6: =$D6/$E6 -> 0.1311004 | H6: =G6+F6 -> 0.18305103
B7: Hornbill Festival Nagaland | C7: 25729666 | D7: 53220652 | E7: 693593924 | F7: =$C7/$E7 -> 0.037096153 | G7: =$D7/$E7 -> 0.076731716 | H7: =G7+F7 -> 0.11382787
B8: Lollapalooza Mumbai | C8: 27249754 | D8: 44591246 | E8: 573358526 | F8: =$C8/$E8 -> 0.047526552 | G8: =$D8/$E8 -> 0.077772012 | H8: =G8+F8 -> 0.12529856
B9: Magnetic Fields Rajasthan | C9: 20962429 | D9: 44144035 | E9: 417295881 | F9: =$C9/$E9 -> 0.050233971 | G9: =$D9/$E9 -> 0.10578594 | H9: =G9+F9 -> 0.15601991
B10: NH7 Pune | C10: 22154036 | D10: 67169601 | E10: 515929887 | F10: =$C10/$E10 -> 0.042940013 | G10: =$D10/$E10 -> 0.13019134 | H10: =G10+F10 -> 0.17313135
B11: Sunburn Goa | C11: 37397648 | D11: 64852790 | E11: 695292216 | F11: =$C11/$E11 -> 0.05378695 | G11: =$D11/$E11 -> 0.093274149 | H11: =G11+F11 -> 0.1470611
B12: Supersonic Bengaluru | C12: 34776787 | D12: 33903753 | E12: 468868182 | F12: =$C12/$E12 -> 0.074171779 | G12: =$D12/$E12 -> 0.072309776 | H12: =G12+F12 -> 0.14648155
B13: VH1 Supersonic Delhi | C13: 26610746 | D13: 33620520 | E13: 459482479 | F13: =$C13/$E13 -> 0.057914604 | G13: =$D13/$E13 -> 0.073170407 | H13: =G13+F13 -> 0.13108501
B14: Ziro Festival Arunachal | C14: 35162471 | D14: 74651155 | E14: 1069812715 | F14: =$C14/$E14 -> 0.032867875 | G14: =$D14/$E14 -> 0.069779648 | H14: =G14+F14 -> 0.10264752
B15: Grand Total | C15: 268574250 | D15: 520726263 | E15: 5964562939 | F15: =$C15/$E15 -> 0.04502832 | G15: =$D15/$E15 -> 0.087303339 | H15: =G15+F15 -> 0.13233166
B17: The reliability of Festivals on Sponsorship
B18: Average contribution of Sponsorship from Total Revenue | D18: =F15 -> 0.04502832
B19: Highest Sponsorship | C19: =INDEX(B5:B14,MATCH(MAX(F5:F14),Stage5!F5:F14,0)) -> Supersonic Bengaluru | D19: =INDEX(F5:F14,MATCH(C19,B5:B14,0)) -> 0.074171779
B20: Lowest Sponsorship | C20: =INDEX(B5:B14,MATCH(MIN(F5:F14),F5:F14,0)) -> Bollywood Music Project | D20: =INDEX(F5:F14,MATCH(C20,B5:B14,0)) -> 0.030791001
B25: Row Labels | C25: Average of Ticket_Price(Rs) | D25: Total number of events | E25: Total Sponsorship Revenue4 | F25: Total Attendance4 | G25: Sponsorship per attendee | H25: Tier Classification
B26: Bollywood Music Project | C26: 3273.6514 | D26: 12 | E26: 24890409 | F26: 241064.86 | G26: =E26/F26 -> 103.25192 | H26: =IF($C26>$C$36,"Premium Tier", "General Tier") -> Premium Tier
B27: Goa Tribal Festival | C27: 2723.8434 | D27: 5 | E27: 13640304 | F27: 78395.1 | G27: =E27/F27 -> 173.99434 | H27: =IF($C27>$C$36,"Premium Tier", "General Tier") -> General Tier
B28: Hornbill Festival Nagaland | C28: 3627.1292 | D28: 8 | E28: 25729666 | F28: 177893.1 | G28: =E28/F28 -> 144.63555 | H28: =IF($C28>$C$36,"Premium Tier", "General Tier") -> Premium Tier
B29: Lollapalooza Mumbai | C29: 3106.5271 | D29: 8 | E29: 27249754 | F29: 162704.2 | G29: =E29/F29 -> 167.48034 | H29: =IF($C29>$C$36,"Premium Tier", "General Tier") -> Premium Tier
B30: Magnetic Fields Rajasthan | C30: 2491.4024 | D30: 7 | E30: 20962429 | F30: 129417.18 | G30: =E30/F30 -> 161.97563 | H30: =IF($C30>$C$36,"Premium Tier", "General Tier") -> General Tier
B31: NH7 Pune | C31: 2563.7778 | D31: 9 | E31: 22154036 | F31: 191933.9 | G31: =E31/F31 -> 115.42534 | H31: =IF($C31>$C$36,"Premium Tier", "General Tier") -> General Tier
B32: Sunburn Goa | C32: 2921.0167 | D32: 13 | E32: 37397648 | F32: 248284.94 | G32: =E32/F32 -> 150.62391 | H32: =IF($C32>$C$36,"Premium Tier", "General Tier") -> Premium Tier
B33: Supersonic Bengaluru | C33: 2358.98 | D33: 10 | E33: 34776787 | F33: 201201.86 | G33: =E33/F33 -> 172.84526 | H33: =IF($C33>$C$36,"Premium Tier", "General Tier") -> General Tier
B34: VH1 Supersonic Delhi | C34: 3410.325 | D34: 8 | E34: 26610746 | F34: 112776.8 | G34: =E34/F34 -> 235.9594 | H34: =IF($C34>$C$36,"Premium Tier", "General Tier") -> Premium Tier
B35: Ziro Festival Arunachal | C35: 2664.5042 | D35: 12 | E35: 35162471 | F35: 258637.78 | G35: =E35/F35 -> 135.95257 | H35: =IF($C35>$C$36,"Premium Tier", "General Tier") -> General Tier
